Workbook

Sheet LISTA DE PRODUCTOS
A1: Item | B1: GRUPO | C1: PRODUCTO | D1: Costo ing + Variacion | E1: % Ingredientes + Variacion | F1: Costo EMPAQ | G1: Costo Ing+emp | H1: % Costo Ing + emp | I1: Costo todo con Combo | J1: Precio de venta | K1: precio sin impuesto al consumo | L1: PRECIO DE VENTAS | M1: MARGEN CONTRIBUCION SIN EMP | N1: % CONTRIBUCION SIN EMP | O1: MARGEN CONTRIBUCION + EMP | P1: % CONTRIBUCION + EMP | Q1: PRECIO ACTUAL COMBO | R1: PRECIO PROVIASIONAL COMBO | S1: DIFERENCIA | T1: NUEVO NOMBRE
A2: 1 | B2: NUEVA LINEA | C2: PASTA ALFREDO | D2: ='PASTA ALFREDO'!E9 -> 9049.1 | E2: =D2/K2 -> 0.51709143 | F2: 0 | G2: =+D2+F2 -> 9049.1 | H2: =G2/K2 -> 0.51709143 | I2: =+D2+F2+H2 -> 9049.6171 | J2: ='PASTA ALFREDO'!E10 -> 18900 | K2: =+J2/1.08 -> 17500 | L2: =J2 -> 18900 | M2: =L2-I2 -> 9850.3829 | N2: =M2/K2 -> 0.56287902 | O2: =L2-K2 -> 1400 | P2: =O2/K2 -> 0.08 | Q2: =#REF! -> #REF! | R2: 0
A3: 2 | B3: NUEVA LINEA | C3: PASTA BOLAÑESA | D3: ='PASTA BOLAÑESA'!E8 -> 10114.1 | E3: =D3/K3 -> 0.54890593 | F3: 0 | G3: =+D3+F3 -> 10114.1 | H3: =G3/K3 -> 0.54890593 | I3: =+D3+F3+H3 -> 10114.649 | J3: ='PASTA BOLAÑESA'!E9 -> 19900 | K3: =+J3/1.08 -> 18425.926 | L3: =J3 -> 19900 | M3: =L3-I3 -> 9785.3511 | N3: =M3/K3 -> 0.53106428 | O3: =L3-K3 -> 1474.0741 | P3: =O3/K3 -> 0.08 | Q3: =#REF! -> #REF! | R3: 0
A4: 3 | B4: NUEVA LINEA | C4: POLLO A LA NARANJA | D4: ='POLLO A LA NARANJA'!E9 -> 8450 | E4: =D4/K4 -> 0.48285714 | F4: 0 | G4: =+D4+F4 -> 8450 | H4: =G4/K4 -> 0.48285714 | I4: =+D4+F4+H4 -> 8450.4829 | J4: ='POLLO A LA NARANJA'!E10 -> 18900 | K4: =+J4/1.08 -> 17500 | L4: =J4 -> 18900 | M4: =L4-I4 -> 10449.517 | N4: =M4/K4 -> 0.59711527 | O4: =L4-K4 -> 1400 | P4: =O4/K4 -> 0.08 | Q4: =#REF! -> #REF! | R4: 0
A5: 4 | B5: NUEVA LINEA | C5: ENSALADA MALAGANA | D5: ='ENSALADA MALAGANA '!E12 -> 7984 | E5: =D5/K5 -> 0.45622857 | F5: 0 | G5: =+D5+F5 -> 7984 | H5: =G5/K5 -> 0.45622857 | I5: =+D5+F5+H5 -> 7984.4562 | J5: ='ENSALADA MALAGANA '!E13 -> 18900 | K5: =+J5/1.08 -> 17500 | L5: =J5 -> 18900 | M5: =L5-I5 -> 10915.544 | N5: =M5/K5 -> 0.62374536 | O5: =L5-K5 -> 1400 | P5: =O5/K5 -> 0.08 | Q5: =#REF! -> #REF! | R5: 0
A6: 5 | B6: NUEVA LINEA | C6: FRIJOLADA | D6: =FRIJOLADA!E9 -> 6039 | E6: =D6/K6 -> 0.34508571 | F6: 0 | G6: =+D6+F6 -> 6039 | H6: =G6/K6 -> 0.34508571 | I6: =+D6+F6+H6 -> 6039.3451 | J6: =FRIJOLADA!E10 -> 18900 | K6: =+J6/1.08 -> 17500 | L6: =J6 -> 18900 | M6: =L6-I6 -> 12860.655 | N6: =M6/K6 -> 0.73489457 | O6: =L6-K6 -> 1400 | P6: =O6/K6 -> 0.08 | Q6: =#REF! -> #REF! | R6: 0
A7: 6 | B7: NUEVA LINEA | C7: LASAÑA BOLOÑESA | D7: =LASAÑA!E9 -> 11737 | E7: =D7/K7 -> 0.5303749 | F7: 0 | G7: =+D7+F7 -> 11737 | H7: =G7/K7 -> 0.5303749 | I7: =+D7+F7+H7 -> 11737.53 | J7: =LASAÑA!E10 -> 23900 | K7: =+J7/1.08 -> 22129.63 | L7: =J7 -> 23900 | M7: =L7-I7 -> 12162.47 | N7: =M7/K7 -> 0.54960114 | O7: =L7-K7 -> 1770.3704 | P7: =O7/K7 -> 0.08 | Q7: =#REF! -> #REF! | R7: 0
A8: 7 | B8: HAMBURGUESA | C8: MALAGANA | D8: =#REF! -> #REF! | E8: =D8/K8 -> #REF! | F8: 0 | G8: =+D8+F8 -> #REF! | H8: =G8/K8 -> #REF! | I8: =+D8+F8+H8 -> #REF! | J8: =#REF! -> #REF! | K8: =+J8/1.08 -> #REF! | L8: =J8 -> #REF! | M8: =L8-I8 -> #REF! | N8: =M8/K8 -> #REF! | O8: =L8-K8 -> #REF! | P8: =O8/K8 -> #REF! | Q8: =#REF! -> #REF! | R8: 0
A9: 8 | B9: HAMBURGUESA | C9: CACIQUE | D9: =#REF! -> #REF! | E9: =D9/K9 -> #REF! | F9: 0 | G9: =+D9+F9 -> #REF! | H9: =G9/K9 -> #REF! | I9: =+D9+F9+H9 -> #REF! | J9: =#REF! -> #REF! | K9: =+J9/1.08 -> #REF! | L9: =J9 -> #REF! | M9: =L9-I9 -> #REF! | N9: =M9/K9 -> #REF! | O9: =L9-K9 -> #REF! | P9: =O9/K9 -> #REF! | Q9: =#REF! -> #REF! | R9: 0
A10: 9 | B10: PLATOS | C10: CHICHARRON OERADO | D10: =#REF! -> #REF! | E10: =D10/K10 -> #REF! | F10: 0 | G10: =+D10+F10 -> #REF! | H10: =G10/K10 -> #REF! | I10: =+D10+F10+H10 -> #REF! | J10: =#REF! -> #REF! | K10: =+J10/1.08 -> #REF! | L10: =J10 -> #REF! | M10: =L10-I10 -> #REF! | N10: =M10/K10 -> #REF! | O10: =L10-K10 -> #REF! | P10: =O10/K10 -> #REF! | Q10: =#REF! -> #REF! | R10: 0
A11: 10 | B11: PLATOS | C11: COSTILLA | D11: =COSTILLA!F7 -> 15288.4 | E11: =D11/K11 -> 0.30020858 | F11: 0 | G11: =+D11+F11 -> 15288.4 | H11: =G11/K11 -> 0.30020858 | I11: =+D11+F11+H11 -> 15288.7 | J11: =COSTILLA!F8 -> 55000 | K11: =+J11/1.08 -> 50925.926 | L11: =J11 -> 55000 | M11: =L11-I11 -> 39711.3 | N11: =M11/K11 -> 0.77978552 | O11: =L11-K11 -> 4074.0741 | P11: =O11/K11 -> 0.08 | Q11: =#REF! -> #REF! | R11: 0
A12: 11 | B12: PLATOS | C12: BONDIOLA | D12: =BONDIOLA!F11 -> 6524.8 | E12: =D12/K12 -> 0.1761696 | F12: 0 | G12: =+D12+F12 -> 6524.8 | H12: =G12/K12 -> 0.1761696 | I12: =+D12+F12+H12 -> 6524.9762 | J12: =BONDIOLA!F12 -> 40000 | K12: =+J12/1.08 -> 37037.037 | L12: =J12 -> 40000 | M12: =L12-I12 -> 33475.024 | N12: =M12/K12 -> 0.90382564 | O12: =L12-K12 -> 2962.963 | P12: =O12/K12 -> 0.08 | Q12: =#REF! -> #REF! | R12: 0
A13: 12 | B13: PLATOS | C13: POLLO DORADO | D13: =#REF! -> #REF! | E13: =D13/K13 -> #REF! | F13: 0 | G13: =+D13+F13 -> #REF! | H13: =G13/K13 -> #REF! | I13: =+D13+F13+H13 -> #REF! | J13: =#REF! -> #REF! | K13: =+J13/1.08 -> #REF! | L13: =J13 -> #REF! | M13: =L13-I13 -> #REF! | N13: =M13/K13 -> #REF! | O13: =L13-K13 -> #REF! | P13: =O13/K13 -> #REF! | Q13: =#REF! -> #REF! | R13: 0
A14: 13 | B14: PIZZA | C14: CARNES | D14: =#REF! -> #REF! | E14: =D14/K14 -> #REF! | F14: 0 | G14: =+D14+F14 -> #REF! | H14: =G14/K14 -> #REF! | I14: =+D14+F14+H14 -> #REF! | J14: =#REF! -> #REF! | K14: =+J14/1.08 -> #REF! | L14: =J14 -> #REF! | M14: =L14-I14 -> #REF! | N14: =M14/K14 -> #REF! | O14: =L14-K14 -> #REF! | P14: =O14/K14 -> #REF! | Q14: =#REF! -> #REF! | R14: 0
A15: 14 | B15: PIZZA | C15: SAMBA | D15: =#REF! -> #REF! | E15: =D15/K15 -> #REF! | F15: 0 | G15: =+D15+F15 -> #REF! | H15: =G15/K15 -> #REF! | I15: =+D15+F15+H15 -> #REF! | J15: =#REF! -> #REF! | K15: =+J15/1.08 -> #REF! | L15: =J15 -> #REF! | M15: =L15-I15 -> #REF! | N15: =M15/K15 -> #REF! | O15: =L15-K15 -> #REF! | P15: =O15/K15 -> #REF! | Q15: =#REF! -> #REF! | R15: 0
A16: 15 | B16: ASADOS | C16: PUNTA DE ANCA | D16: =#REF! -> #REF! | E16: =D16/K16 -> #REF! | F16: 0 | G16: =+D16+F16 -> #REF! | H16: =G16/K16 -> #REF! | I16: =+D16+F16+H16 -> #REF! | J16: =#REF! -> #REF! | K16: =+J16/1.08 -> #REF! | L16: =J16 -> #REF! | M16: =L16-I16 -> #REF! | N16: =M16/K16 -> #REF! | O16: =L16-K16 -> #REF! | P16: =O16/K16 -> #REF! | Q16: =#REF! -> #REF! | R16: 0
A17: 16 | B17: ASADOS | C17: CHURRASCO | D17: =#REF! -> #REF! | E17: =D17/K17 -> #REF! | F17: 0 | G17: =+D17+F17 -> #REF! | H17: =G17/K17 -> #REF! | I17: =+D17+F17+H17 -> #REF! | J17: =#REF! -> #REF! | K17: =+J17/1.08 -> #REF! | L17: =J17 -> #REF! | M17: =L17-I17 -> #REF! | N17: =M17/K17 -> #REF! | O17: =L17-K17 -> #REF! | P17: =O17/K17 -> #REF! | Q17: =#REF! -> #REF! | R17: 0
E18: =D18/K18 -> #DIV/0! | F18: 0 | G18: =+D18+F18 -> 0 | H18: =G18/K18 -> #DIV/0! | I18: =+D18+F18+H18 -> #DIV/0! | J18: 0 | K18: =+J18/1.08 -> 0 | L18: =J18 -> 0 | M18: =L18-I18 -> #DIV/0! | N18: =M18/K18 -> #DIV/0! | O18: =L18-K18 -> 0 | P18: =O18/K18 -> #DIV/0! | Q18: =#REF! -> #REF! | R18: 0
E19: =D19/K19 -> #DIV/0! | F19: 0 | G19: =+D19+F19 -> 0 | H19: =G19/K19 -> #DIV/0! | I19: =+D19+F19+H19 -> #DIV/0! | J19: 0 | K19: =+J19/1.08 -> 0 | L19: =J19 -> 0 | M19: =L19-I19 -> #DIV/0! | N19: =M19/K19 -> #DIV/0! | O19: =L19-K19 -> 0 | P19: =O19/K19 -> #DIV/0! | Q19: =#REF! -> #REF! | R19: 0

Sheet BONDIOLA
B2: ENSALDA DE BONDIOLA ACARAMELADA | C2: CANT. | D2: GRAMAJE O UNIDAD | E2: PRECIO | F2: PRECIO | G2: INGREDIENTES | H2: PREPARACIÓN
B3: TIEMPO DE PREPARACION | C3: 100 | D3: Gr | E3: 18 | F3: =C3*E3 -> 1800 | G3: Jamón de Bondiola Acaramelada
B4: 12 minutos | C4: 100 | D4: Gr | E4: 20 | F4: =C4*E4 -> 2000 | G4: Mix de Lechugas
C5: 10 | D5: Gr | E5: 6.4 | F5: =C5*E5 -> 64 | G5: Miel de Caña
C6: 10 | D6: Gr | E6: 8 | F6: =C6*E6 -> 80 | G6: Chuney de piña
C7: 20 | D7: Gr | E7: 22 | F7: =C7*E7 -> 440 | G7: Queso costeño
C8: 10 | D8: Gr | E8: 120 | F8: =C8*E8 -> 1200 | G8: Almendras rebanadas
C9: 30 | D9: Gr | E9: 18.36 | F9: =C9*E9 -> 550.8 | G9: Tomate cherry
C10: 30 | D10: Gr | E10: 13 | F10: =C10*E10 -> 390 | G10: Fresa
F11: =SUM(F3:F10) -> 6524.8
F12: 40000
B13: tener en cuenta | C13: Producto quemado o que no cumpla con las caracteristicas no se debe sacar
B15: JAMON DE BONDIOLA ACARMELADO | C15: CANT. | D15: GRAMAJE O UNIDAD | E15: PRECIO | F15: PRECIO | G15: INGREDIENTES | H15: PREPARACIÓN
B16: 12 TIEMPO DE PREPARACION | C16: 1300 | D16: Gr | E16: 20 | F16: =C16*E16 -> 26000 | G16: Bondiola
B17: 10 minutos | C17: 10 | D17: Ml | E17: 118.6 | F17: =C17*E17 -> 1186 | G17: Viche
C18: 5 | D18: Gr | E18: 24 | F18: =C18*E18 -> 120 | G18: Comino
C19: 10 | D19: Gr | E19: 48 | F19: =C19*E19 -> 480 | G19: Paprika
C20: 80 | D20: Gr | E20: 8 | F20: =C20*E20 -> 640 | G20: Panela granulada
C21: 5 | D21: Gr | E21: 52 | F21: =C21*E21 -> 260 | G21: Pimienta negra
C22: 40 | D22: Gr | E22: 2.4 | F22: =C22*E22 -> 96 | G22: Sal refinada
C23: 200 | D23: Gr | E23: 4.4 | F23: =C23*E23 -> 880 | G23: Azucar
C24: =SUM(C16:C23) -> 1650 | F24: =SUM(F16:F23) -> 29662
F25: =F24/C24 -> 17.97697
B26: tener en cuenta | C26: Producto quemado o que no cumpla con las caracteristicas no se debe sacar
B28: MIEL DE CAÑA | C28: CANT. | D28: GRAMAJE O UNIDAD | E28: PRECIO | F28: PRECIO | G28: INGREDIENTES | H28: PREPARACIÓN
B29: 12 TIEMPO DE PREPARACION | C29: 800 | D29: Gr | E29: 6.11 | F29: =C29*E29 -> 4888 | G29: Panela
B30: 10 minutos | C30: 10 | D30: Gr | E30: 56.6 | F30: =C30*E30 -> 566 | G30: Poleo
C31: 50 | D31: Gr | E31: 45 | F31: =C31*E31 -> 2250 | G31: Tomillo
C32: 30 | D32: Ml | E32: 5 | F32: =C32*E32 -> 150 | G32: Fecula
C33: 100 | D33: Gr | E33: 3.99 | F33: =C33*E33 -> 399 | G33: Jugo de Naranja
C34: 500 | D34: Gr | E34: 2.6 | F34: =C34*E34 -> 1300 | G34: Agua
C35: =SUM(C29:C34) -> 1490 | F35: =SUM(F29:F34) -> 9553
F36: =F35/C35 -> 6.4114094
B39: tener en cuenta | C39: Producto quemado o que no cumpla con las caracteristicas no se debe sacar
B41: CHUNEY DE PIÑA | C41: CANT. | D41: GRAMAJE O UNIDAD | E41: PRECIO | F41: PRECIO | G41: INGREDIENTES | H41: PREPARACIÓN
B42: 12 TIEMPO DE PREPARACION | C42: 1155 | D42: Gr | E42: 1.98 | F42: =C42*E42 -> 2286.9 | G42: PIÑA
B43: 10 minutos | C43: 100 | D43: Gr | E43: 9.4 | F43: =C43*E43 -> 940 | G43: ALBAHACA GENOVESA
C44: 100 | D44: Gr | E44: 37.48 | F44: =C44*E44 -> 3748 | G44: ESENCIA COCO
C45: 1500 | D45: Gr | E45: 4.4 | F45: =C45*E45 -> 6600 | G45: AZUCAR
C46: 200 | D46: Ml | E46: 5 | F46: =C46*E46 -> 1000 | G46: MAICENA
...

Sheet COSTILLA
B2: COSTILLA SOUS VIDE | C2: CANT. | D2: GRAMAJE O UNIDAD | E2: PRECIO | F2: PRECIO | G2: INGREDIENTES | H2: PREPARACIÓN
B3: TIEMPO DE PREPARACION | C3: 500 | D3: Gr | E3: 26 | F3: =C3*E3 -> 13000 | G3: COSTILLA TIPO LLANERA
C4: 1 | D4: Gr | E4: 854 | F4: =C4*E4 -> 854 | G4: ENSALADA FRESCA
C5: 140 | D5: Gr | E5: 7.16 | F5: =C5*E5 -> 1002.4 | G5: PAPAS AMARILLAS EN CASCO
C6: 40 | D6: Gr | E6: 10.8 | F6: =C6*E6 -> 432 | G6: ALIOLI DE CILANTRO
F7: =SUM(F3:F6) -> 15288.4
F8: 55000
B12: tener en cuenta | C12: Producto quemado o que no cumpla con las caracteristicas no se debe sacar
B14: ENSALADA | C14: CANT. | D14: GRAMAJE O UNIDAD | E14: PRECIO | F14: PRECIO | G14: INGREDIENTES | H14: PREPARACIÓN
B15: 12 TIEMPO DE PREPARACION | C15: 15 | D15: Gr | E15: 1.98 | F15: =C15*E15 -> 29.7 | G15: lechuga
B16: 10 minutos | C16: 25 | D16: Gr | E16: 9.4 | F16: =C16*E16 -> 235 | G16: Tomate Cherry
C17: 15 | D17: Gr | E17: 37.48 | F17: =C17*E17 -> 562.2 | G17: Cebolla Roja
C18: 5 | D18: Ml | E18: 4.4 | F18: =C18*E18 -> 22 | G18: Zumo limon
C19: 1 | D19: Gr | E19: 5 | F19: =C19*E19 -> 5 | G19: Sal
F20: =SUM(F15:F19) -> 853.9
B23: tener en cuenta | C23: Producto quemado o que no cumpla con las caracteristicas no se debe sacar
B25: COSTILLA | C25: CANT. | D25: GRAMAJE O UNIDAD | E25: PRECIO | F25: PRECIO | G25: INGREDIENTES | H25: PREPARACIÓN
B26: 12 TIEMPO DE PREPARACION | C26: 500 | D26: Gr | E26: 26.6 | F26: =C26*E26 -> 13300 | G26: Costilla tipo llanera
B27: 10 minutos | C27: 11.25 | D27: Gr | E27: 26 | F27: =C27*E27 -> 292.5 | G27: Pasta de ajo
C28: 20 | D28: Gr | E28: 3.8 | F28: =C28*E28 -> 76 | G28: Cebolla
C29: 1.25 | D29: Gr | E29: 45 | F29: =C29*E29 -> 56.25 | G29: Tomillo
C30: 1.25 | D30: Gr | E30: 52 | F30: =C30*E30 -> 65 | G30: Pimenta
C31: 15 | D31: Gr | E31: 48 | F31: =C31*E31 -> 720 | G31: Naranja
C32: 0.6 | D32: Gr | E32: 48 | F32: =C32*E32 -> 28.8 | G32: Paprika
C33: 15 | D33: Gr | E33: 32 | F33: =C33*E33 -> 480 | G33: Vinagre de manzana
C34: 1.25 | D34: Gr | E34: 24 | F34: =C34*E34 -> 30 | G34: Comino
C35: 6.25 | D35: Gr | E35: 2.6 | F35: =C35*E35 -> 16.25 | G35: Sal
C36: =SUM(C26:C35) -> 571.85 | F36: =SUM(F26:F35) -> 15064.8
F37: =F36/C36 -> 26.343971
B38: tener en cuenta | C38: Producto quemado o que no cumpla con las caracteristicas no se debe sacar

Sheet PASTA ALFREDO
B2: PASTA ALFREDO lunes | C2: CANT. | D2: GRAMAJE O UNIDAD | E2: PRECIO | F2: INGREDIENTES | G2: PREPARACIÓN
B3: TIEMPO DE PREPARACION | C3: 120 | D3: Gr | E3: 3090 | F3: Pasta alfredo
B4: 12 minutos | C4: 120 | D4: Gr | E4: 2407 | F4: Bondiola
C5: 90 | D5: Gr | E5: 752.1 | F5: Ensalada
C6: 15 | D6: Ml | E6: 150 | F6: miel de caña
C7: 225 | D7: Gr | E7: 1750 | F7: Cremas Champiñones
C8: 2 | D8: Und | E8: 900 | F8: Aguapanela
E9: =SUM(E3:E8) -> 9049.1
E10: 18900
E11: =E9/E10 -> 0.47878836
B12: tener en cuenta | C12: Producto quemado o que no cumpla con las caracteristicas no se debe sacar
B14: SUB SALS ALFREDO | C14: CANT. | D14: GRAMAJE O UNIDAD | E14: PRECIO | F14: INGREDIENTES | G14: PREPARACIÓN
B15: TIEMPO DE PREPARACION | C15: 120 | D15: Gr | E15: 2640 | F15: Mantequilla
B16: 12 minutos | C16: 750 | D16: Gr | E16: 12000 | F16: Crema de Leche
C17: 10 | D17: Gr | E17: 1500 | F17: pasta de ajo
C18: 200 | D18: Gr | E18: 4320 | F18: Parmesano
C19: 2 | D19: Gr | E19: 200 | F19: pimienta
C20: 1 | D20: Pisca | E20: 500 | F20: Nues Mozcada
C21: 10 | D21: Gr | E21: 4.2 | F21: Sal
C22: 120 | D22: Gr | E22: 1488 | F22: Pasta fetuccine
E23: =SUM(E15:E22) -> 22652.2 | F23: Pasta fetuccine
B24: tener en cuenta | C24: Producto quemado o que no cumpla con las caracteristicas no se debe sacar
B26: ENSALADA CASA L-D | C26: CANT. | D26: GRAMAJE O UNIDAD | E26: PRECIO | F26: INGREDIENTES | G26: PREPARACIÓN
B27: TIEMPO DE PREPARACION | C27: 15 | D27: Gr | E27: 144 | F27: lechuga
B28: 12 minutos | C28: 25 | D28: Gr | E28: 335 | F28: Tomate Cherry
C29: 15 | D29: Gr | E29: 68.7 | F29: Cebolla Roja
C30: 5 | D30: Ml | E30: 200 | F30: Zumo limon
C31: 1 | D31: Gr | E31: 4.4 | F31: Sal
E32: =SUM(E27:E31) -> 752.1
E33: 0
E34: 0
B36: tener en cuenta | C36: Producto quemado o que no cumpla con las caracteristicas no se debe sacar

Sheet PASTA BOLAÑESA
B2: PASTA BOLOÑESA | C2: CANT. | D2: GRAMAJE O UNIDAD | E2: PRECIO | F2: INGREDIENTES | G2: PREPARACIÓN
B3: TIEMPO DE PREPARACION | C3: 400 | D3: Gr | E3: 6110 | F3: Pasta Boloñesa
B4: 12 minutos | C4: 3 | D4: Gr | E4: 602 | F4: Tostadas de pan
C5: 225 | D5: Gr | E5: 1750 | F5: Cremas Champiñones
C6: 90 | D6: Gr | E6: 752.1 | F6: Ensalada
C7: 2 | D7: Und | E7: 900 | F7: Aguapanela
E8: =SUM(E3:E7) -> 10114.1
E9: 19900
E10: =E8/E9 -> 0.50824623
B12: tener en cuenta | C12: Producto quemado o que no cumpla con las caracteristicas no se debe sacar
B14: SUB PASTA BOLOÑESA | C14: CANT. | D14: GRAMAJE O UNIDAD | E14: PRECIO | F14: INGREDIENTES | G14: PREPARACIÓN
B15: TIEMPO DE PREPARACION | C15: 100 | D15: Gr | E15: 2700 | F15: Carne molida
B16: 12 minutos | C16: 40 | D16: Gr | E16: 106 | F16: Cebolla cabezona
C17: 5 | D17: Gr | E17: 49.5 | F17: Ajo
C18: 20 | D18: Gr | E18: 46 | F18: Zanahoria
C19: 10 | D19: Gr | E19: 200 | F19: Apio
C20: 80 | D20: Gr | E20: 416 | F20: Tomate (triturado)
C21: 14 | D21: Gr | E21: 868 | F21: Aceite de oliva
C22: 2 | D22: Gr | E22: 4.2 | F22: Sal
C23: 1 | D23: Gr | E23: 156 | F23: Oregano Seco
C24: 1 | D24: Gr | E24: 100 | F24: Pimienta
C25: 1 | D25: Gr | E25: 100 | F25: Laurel
C26: 110 | D26: Gr | E26: 1364 | F26: Pasta fetuccine
D27: Gr | E27: =SUM(E15:E26) -> 6109.7
B28: tener en cuenta | C28: Producto quemado o que no cumpla con las caracteristicas no se debe sacar
B30: TOSTADAS DE AJO Y OREGANO | C30: CANT. | D30: GRAMAJE O UNIDAD | E30: PRECIO | F30: INGREDIENTES | G30: PREPARACIÓN
B31: TIEMPO DE PREPARACION | C31: 3 | D31: Gr | E31: 216 | F31: Pan Frances
B32: 12 minutos | C32: 10 | D32: Gr | E32: 220 | F32: mantequilla
C33: 1 | D33: Gr | E33: 9.9 | F33: Ajo
C34: 1 | D34: Gr | E34: 156 | F34: Oregano
D35: Gr | E35: 0
E36: =SUM(E31:E35) -> 601.9
E37: 0
E38: 0
B40: tener en cuenta | C40: Producto quemado o que no cumpla con las caracteristicas no se debe sacar
B42: ENSALADA CASA L-D | C42: CANT. | D42: GRAMAJE O UNIDAD | E42: PRECIO | F42: INGREDIENTES | G42: PREPARACIÓN
B43: TIEMPO DE PREPARACION | C43: 15 | D43: Gr | E43: 144 | F43: lechuga
B44: 12 minutos | C44: 25 | D44: Gr | E44: 335 | F44: Tomate Cherry
C45: 15 | D45: Gr | E45: 68.7 | F45: Cebolla Roja
C46: 5 | D46: Ml | E46: 200 | F46: Zumo limon
...

Sheet ENSALADA MALAGANA 
B2: ENSALADA MALAGANA | C2: CANT. | D2: GRAMAJE O UNIDAD | E2: PRECIO | F2: INGREDIENTES | G2: PREPARACIÓN
B3: TIEMPO DE PREPARACION | C3: 40 | D3: Gr | E3: 480 | F3: maiz salteado
B4: 12 minutos | C4: 80 | D4: Gr | E4: 768 | F4: lechuga
C5: 40 | D5: Gr | E5: 536 | F5: Tomate Cherry
C6: 100 | D6: Gr | E6: 690 | F6: papas a la francesa
C7: 70 | D7: Gr | E7: 2300 | F7: Chuleta
C8: 30 | D8: Gr | E8: 300 | F8: cebolla encurtida
C9: 10 | D9: Gr | E9: 260 | F9: Ajonjoli Negro
C10: 225 | D10: Gr | E10: 1750 | F10: Cremas Champiñones
C11: 2 | D11: Und | E11: 900 | F11: Aguapanela
E12: =SUM(E3:E11) -> 7984
E13: 18900
E14: =E12/E13 -> 0.42243386
B15: tener en cuenta | C15: Producto quemado o que no cumpla con las caracteristicas no se debe sacar
G16: PREPARACIÓN
B17: SUB MILANESA | C17: CANT. | D17: GRAMAJE O UNIDAD | E17: PRECIO | F17: INGREDIENTES
B18: TIEMPO DE PREPARACION | C18: 150 | D18: Gr | E18: 3150 | F18: Cerdo
B19: 12 minutos | C19: 1 | D19: Und | E19: 250 | F19: Rebosado
C20: 65 | D20: Gr | E20: 1183 | F20: Panko
D21: Gr | E21: 0
D22: Gr | E22: 0
D23: Gr | E23: 0
E24: 0
E25: =SUM(E18:E24) -> 4583
E26: 0
B28: tener en cuenta | C28: Producto quemado o que no cumpla con las caracteristicas no se debe sacar
G29: PREPARACIÓN
B30: SUB CEBOLLA ENCURTIDA | C30: CANT. | D30: GRAMAJE O UNIDAD | E30: PRECIO | F30: INGREDIENTES
B31: TIEMPO DE PREPARACION | C31: 500 | D31: Gr | E31: 2290 | F31: Cebolla Roja
B32: 12 minutos | C32: 250 | D32: Gr | E32: 1900 | F32: Vinagre Blanco
C33: 250 | D33: Gr | E33: 0 | F33: Agua
C34: 10 | D34: Gr | E34: 35 | F34: Azucar
C35: 10 | D35: Gr | E35: 24 | F35: Sal
D36: Gr | E36: 0
C37: 1020 | E37: =SUM(E31:E36) -> 4249
E38: 0
B40: tener en cuenta | C40: Producto quemado o que no cumpla con las caracteristicas no se debe sacar
B42: SUB REBOSADO | C42: CANT. | D42: GRAMAJE O UNIDAD | E42: PRECIO | F42: INGREDIENTES | G42: PREPARACIÓN
B43: TIEMPO DE PREPARACION | C43: 250 | D43: Gr | E43: 1260 | F43: Fecula
B44: 12 minutos | C44: 250 | D44: Gr | E44: 902 | F44: harina de trigo
...

Sheet POLLO A LA NARANJA
B2: POLLO A LA NARANJA | C2: CANT. | D2: GRAMAJE O UNIDAD | E2: PRECIO | F2: INGREDIENTES | G2: PREPARACIÓN
B3: TIEMPO DE PREPARACION | C3: 150 | D3: Gr | E3: 4520 | F3: Pollo a la naranja
B4: 12 minutos | C4: 120 | D4: Gr | E4: 528 | F4: Arroz
C5: 90 | D5: Gr | E5: 752 | F5: Ensalada
C6: 2 | D6: Und | E6: 900 | F6: Aguapanela
C7: 225 | D7: Gr | E7: 1750 | F7: Cremas Champiñones
E8: 0
E9: =SUM(E3:E8) -> 8450
E10: 18900
E11: =E9/E10 -> 0.44708995
B12: tener en cuenta | C12: Producto quemado o que no cumpla con las caracteristicas no se debe sacar
B14: POLLO A LA NARANJA | C14: CANT. | D14: GRAMAJE O UNIDAD | E14: PRECIO | F14: INGREDIENTES | G14: PREPARACIÓN
B15: TIEMPO DE PREPARACION | C15: 150 | D15: Gr | E15: 3450 | F15: Pollo
B16: 12 minutos | C16: 100 | D16: Gr | E16: 600 | F16: Zumo de Naranja
C17: 1 | D17: Gr | E17: 100 | F17: Ralladura de Limon
C18: 5 | D18: Gr | E18: 100 | F18: Salsa Soya
C19: 6 | D19: Gr | E19: 20 | F19: Azucar
C20: 5 | D20: Gr | E20: 50 | F20: Vinagre
C21: 5 | D21: Gr | E21: 50 | F21: Fecula
C22: 5 | D22: Gr | E22: 50 | F22: Aceite
C23: 1 | D23: Pisca | E23: 100 | F23: Pimienta
E24: =SUM(E15:E23) -> 4520
B25: tener en cuenta | C25: Producto quemado o que no cumpla con las caracteristicas no se debe sacar
B27: ENSALADA CASA L-D | C27: CANT. | D27: GRAMAJE O UNIDAD | E27: PRECIO | F27: INGREDIENTES | G27: PREPARACIÓN
B28: TIEMPO DE PREPARACION | C28: 15 | D28: Gr | E28: 144 | F28: lechuga
B29: 12 minutos | C29: 25 | D29: Gr | E29: 335 | F29: Tomate Cherry
C30: 15 | D30: Gr | E30: 68.7 | F30: Cebolla Roja
C31: 5 | D31: Ml | E31: 200 | F31: Zumo limon
C32: 1 | D32: Gr | E32: 4.4 | F32: Sal
E33: =SUM(E28:E32) -> 752.1
E34: 0
E35: 0
B37: tener en cuenta | C37: Producto quemado o que no cumpla con las caracteristicas no se debe sacar
G38: PREPARACIÓN
B39: ADEREZO DE COCO | C39: CANT. | D39: GRAMAJE O UNIDAD | E39: PRECIO | F39: INGREDIENTES
B40: TIEMPO DE PREPARACION | D40: Gr | E40: 0
B41: 12 minutos | D41: Gr | E41: 0
D42: Gr | E42: 0
D43: Gr | E43: 0
D44: Gr | E44: 0
...

Sheet FRIJOLADA
B2: FRIIJOLADA viernes | C2: CANT. | D2: GRAMAJE O UNIDAD | E2: Precio | F2: INGREDIENTES | G2: PREPARACIÓN
B3: TIEMPO DE PREPARACION | C3: 225 | D3: ML | E3: 575 | F3: Frijoles
B4: 12 minutos | C4: 120 | D4: Gr | E4: 3048 | F4: Chicharron
C5: 120 | D5: Gr | E5: 528 | F5: Arroz
C6: 90 | D6: Gr | E6: 680 | F6: Ensalada remolacha
C7: 70 | D7: Gr | E7: 308 | F7: Maduro
C8: 2 | D8: Und | E8: 900 | F8: Aguapanela
E9: =SUM(E3:E8) -> 6039
E10: 18900
E11: =E9/E10 -> 0.31952381
B12: tener en cuenta | C12: Producto quemado o que no cumpla con las caracteristicas no se debe sacar
B14: ENSALADA remolacha | C14: CANT. | D14: GRAMAJE O UNIDAD | E14: Precio | F14: INGREDIENTES | G14: PREPARACIÓN
B15: TIEMPO DE PREPARACION | C15: 40 | D15: Gr | E15: 119.2 | F15: Remolacha
B16: 12 minutos | C16: 15 | D16: Gr | E16: 68.7 | F16: Zanahoria
C17: 25 | D17: Gr | E17: 492 | F17: Mayonesa
E18: =SUM(E15:E17) -> 679.9
B24: tener en cuenta | C24: Producto quemado o que no cumpla con las caracteristicas no se debe sacar
B26: SUB FRIJOLES | C26: CANT. | D26: GRAMAJE O UNIDAD | E26: Precio | F26: INGREDIENTES | G26: PREPARACIÓN
B27: TIEMPO DE PREPARACION | C27: 40 | D27: Gr | E27: 345 | F27: Frijol
B28: 12 minutos | C28: 15 | D28: Gr | E28: 68.7 | F28: Zanahoria
C29: 15 | D29: Gr | E29: 66 | F29: Cebolla larga
C30: 5 | D30: Gr | E30: 10 | F30: Papa
C31: 10 | D31: Gr | E31: 24 | F31: Zapallo
C32: 10 | D32: Gr | E32: 18.4 | F32: Zanahoria
C33: 10 | D33: Gr | E33: 43 | F33: Tomate chonto
E34: =SUM(E27:E33) -> 575.1
B36: tener en cuenta | C36: Producto quemado o que no cumpla con las caracteristicas no se debe sacar

Sheet LASAÑA
B2: LASAÑA | C2: CANT. | D2: GRAMAJE O UNIDAD | E2: PRECIO | F2: INGREDIENTES | G2: PREPARACIÓN
B3: TIEMPO DE PREPARACION | C3: 1.5 | D3: UND | E3: 2035 | F3: pasta lamina
B4: 12 minutos | C4: 250 | D4: Gr | E4: 3300 | F4: boloñesa
C5: 160 | D5: Gr | E5: 2600 | F5: bechamel
C6: 100 | D6: Gr | E6: 2700 | F6: Carne Molida
C7: 3 | D7: Und | E7: 602 | F7: Tostadas de pan
C8: 1 | D8: Und | E8: 500 | F8: Molde
E9: =SUM(E3:E8) -> 11737
E10: 23900
E12: =E9/E10 -> 0.49108787
B13: tener en cuenta | C13: Producto quemado o que no cumpla con las caracteristicas no se debe sacar
G14: PREPARACIÓN
B15: SUB BECHAMEL | C15: CANT. | D15: GRAMAJE O UNIDAD | E15: PRECIO | F15: INGREDIENTES
B16: TIEMPO DE PREPARACION | C16: 80 | D16: Gr | E16: 288.8 | F16: harina de trigo
B17: 12 minutos | C17: 80 | D17: Gr | E17: 1760 | F17: mantequilla
C18: c/n | D18: Gr | E18: 310 | F18: nuez moscada
C19: 1000 | D19: ml | E19: 12000 | F19: leche
C20: c/n | D20: Gr | E20: 300 | F20: pimienta
E21: 0 | F21: sal
E22: =SUM(E16:E21) -> 14658.8
E23: 0
B26: tener en cuenta | C26: Producto quemado o que no cumpla con las caracteristicas no se debe sacar
B29: SUB SALSA BOLOÑESA | C29: CANT. | D29: GRAMAJE O UNIDAD | E29: PRECIO | F29: INGREDIENTES | G29: PREPARACIÓN
B30: TIEMPO DE PREPARACION | C30: 100 | D30: Gr | E30: 2700 | F30: Carne molida
B31: 12 minutos | C31: 40 | D31: Gr | E31: 106 | F31: Cebolla cabezona
C32: 5 | D32: Gr | E32: 49.5 | F32: Ajo
C33: 20 | D33: Gr | E33: 46 | F33: Zanahoria
C34: 10 | D34: Gr | E34: 200 | F34: Apio
C35: 80 | D35: Gr | E35: 416 | F35: Tomate (triturado)
C36: 15 | D36: Gr | E36: 547 | F36: Psata de tomate
C37: 14 | D37: Gr | E37: 868 | F37: Aceite de oliva
C38: 2 | D38: Gr | E38: 4.2 | F38: Sal
C39: 1 | D39: Gr | E39: 156 | F39: Oregano Seco
C40: 1 | D40: Gr | E40: 100 | F40: Pimienta
C41: 1 | D41: Gr | E41: 100 | F41: Laurel
D42: Gr | E42: =SUM(E30:E41) -> 5292.7
B43: tener en cuenta | C43: Producto quemado o que no cumpla con las caracteristicas no se debe sacar
