Workbook

Sheet PLANTILLAS 
B3: PASTA CARBONARA | H3: PASTA CARBONARA | N3: PASTA CARBONARA
B4: INGREDIENTES | C4: CANTIDAD | D4: UND MEDIDA | E4: COS/GR | F4: VALOR | H4: INGREDIENTES | I4: CANTIDAD | J4: UND MEDIDA | K4: COS/GR | L4: VALOR | N4: INGREDIENTES | O4: CANTIDAD | P4: UND MEDIDA | Q4: COS/GR | R4: VALOR
D5: gr | F5: =C5*E5 -> 0 | J5: gr | L5: =I5*K5 -> 0 | P5: gr | R5: =O5*Q5 -> 0
D6: gr | F6: =C6*E6 -> 0 | J6: gr | L6: =I6*K6 -> 0 | P6: gr | R6: =O6*Q6 -> 0
D7: gr | F7: =C7*E7 -> 0 | J7: gr | L7: =I7*K7 -> 0 | P7: gr | R7: =O7*Q7 -> 0
D8: gr | F8: =C8*E8 -> 0 | J8: gr | L8: =I8*K8 -> 0 | P8: gr | R8: =O8*Q8 -> 0
D9: gr | F9: =C9*E9 -> 0 | J9: gr | L9: =I9*K9 -> 0 | P9: gr | R9: =O9*Q9 -> 0
D10: gr | F10: =C10*E10 -> 0 | J10: gr | L10: =I10*K10 -> 0 | P10: gr | R10: =O10*Q10 -> 0
D11: gr | F11: =C11*E11 -> 0 | J11: gr | L11: =I11*K11 -> 0 | P11: gr | R11: =O11*Q11 -> 0
F12: =C12*E12 -> 0 | L12: =I12*K12 -> 0 | R12: =O12*Q12 -> 0
F13: =C13*E13 -> 0 | L13: =I13*K13 -> 0 | R13: =O13*Q13 -> 0
B14: MATERIAL DE EMPAQUE | H14: MATERIAL DE EMPAQUE | N14: MATERIAL DE EMPAQUE
F15: =C15*140 -> 0 | L15: =I15*140 -> 0 | R15: =O15*140 -> 0
F16: =C16*140 -> 0 | L16: =I16*140 -> 0 | R16: =O16*140 -> 0
F17: =C17*140 -> 0 | L17: =I17*140 -> 0 | R17: =O17*140 -> 0
B18: COSTO + PRECIO DE VENTA | H18: COSTO + PRECIO DE VENTA | N18: COSTO + PRECIO DE VENTA
B19: COSTO DE INGREDIENTES | F19: =(F5+F6+F7+F8+F9+F10+F11+F12+F13+F17) -> 0 | H19: COSTO DE INGREDIENTES | L19: =(L5+L6+L7+L8+L9+L10+L11+L12+L13+L17) -> 0 | N19: COSTO DE INGREDIENTES | R19: =(R5+R6+R7+R8+R9+R10+R11+R12+R13+R17) -> 0
B20: MARGEN DE ERROR O VARIACION 10% | F20: =F19*0.1 -> 0 | H20: MARGEN DE ERROR O VARIACION 10% | L20: =L19*0.1 -> 0 | N20: MARGEN DE ERROR O VARIACION 10% | R20: =R19*0.1 -> 0
B21: COSTO TOTAL DE LA PREPARACION | F21: =SUM(F19:F20) -> 0 | H21: COSTO TOTAL DE LA PREPARACION | L21: =SUM(L19:L20) -> 0 | N21: COSTO TOTAL DE LA PREPARACION | R21: =SUM(R19:R20) -> 0
B22: PRECIO DE VENTA | F22: 30000 | H22: PRECIO DE VENTA | L22: 30000 | N22: PRECIO DE VENTA | R22: 30000
B25: PASTA CARBONARA | H25: PASTA CARBONARA | N25: PASTA CARBONARA
B26: INGREDIENTES | C26: CANTIDAD | D26: UND MEDIDA | E26: COS/GR | F26: VALOR | H26: INGREDIENTES | I26: CANTIDAD | J26: UND MEDIDA | K26: COS/GR | L26: VALOR | N26: INGREDIENTES | O26: CANTIDAD | P26: UND MEDIDA | Q26: COS/GR | R26: VALOR
D27: gr | F27: =C27*E27 -> 0 | J27: gr | L27: =I27*K27 -> 0 | P27: gr | R27: =O27*Q27 -> 0
D28: gr | F28: =C28*E28 -> 0 | J28: gr | L28: =I28*K28 -> 0 | P28: gr | R28: =O28*Q28 -> 0
D29: gr | F29: =C29*E29 -> 0 | J29: gr | L29: =I29*K29 -> 0 | P29: gr | R29: =O29*Q29 -> 0
D30: gr | F30: =C30*E30 -> 0 | J30: gr | L30: =I30*K30 -> 0 | P30: gr | R30: =O30*Q30 -> 0
D31: gr | F31: =C31*E31 -> 0 | J31: gr | L31: =I31*K31 -> 0 | P31: gr | R31: =O31*Q31 -> 0
D32: gr | F32: =C32*E32 -> 0 | J32: gr | L32: =I32*K32 -> 0 | P32: gr | R32: =O32*Q32 -> 0
D33: gr | F33: =C33*E33 -> 0 | J33: gr | L33: =I33*K33 -> 0 | P33: gr | R33: =O33*Q33 -> 0
F34: =C34*E34 -> 0 | L34: =I34*K34 -> 0 | R34: =O34*Q34 -> 0
F35: =C35*E35 -> 0 | L35: =I35*K35 -> 0 | R35: =O35*Q35 -> 0
B36: MATERIAL DE EMPAQUE | H36: MATERIAL DE EMPAQUE | N36: MATERIAL DE EMPAQUE
F37: =C37*140 -> 0 | L37: =I37*140 -> 0 | R37: =O37*140 -> 0
F38: =C38*140 -> 0 | L38: =I38*140 -> 0 | R38: =O38*140 -> 0
F39: =C39*140 -> 0 | L39: =I39*140 -> 0 | R39: =O39*140 -> 0
B40: COSTO + PRECIO DE VENTA | H40: COSTO + PRECIO DE VENTA | N40: COSTO + PRECIO DE VENTA
B41: COSTO DE INGREDIENTES | F41: =(F27+F28+F29+F30+F31+F32+F33+F34+F35+F39) -> 0 | H41: COSTO DE INGREDIENTES | L41: =(L27+L28+L29+L30+L31+L32+L33+L34+L35+L39) -> 0 | N41: COSTO DE INGREDIENTES | R41: =(R27+R28+R29+R30+R31+R32+R33+R34+R35+R39) -> 0
B42: MARGEN DE ERROR O VARIACION 10% | F42: =F41*0.1 -> 0 | H42: MARGEN DE ERROR O VARIACION 10% | L42: =L41*0.1 -> 0 | N42: MARGEN DE ERROR O VARIACION 10% | R42: =R41*0.1 -> 0
B43: COSTO TOTAL DE LA PREPARACION | F43: =SUM(F41:F42) -> 0 | H43: COSTO TOTAL DE LA PREPARACION | L43: =SUM(L41:L42) -> 0 | N43: COSTO TOTAL DE LA PREPARACION | R43: =SUM(R41:R42) -> 0
B44: PRECIO DE VENTA | F44: 30000 | H44: PRECIO DE VENTA | L44: 30000 | N44: PRECIO DE VENTA | R44: 30000
...

Sheet ENTREGABLES
B2: La biblia de los productos
B3: Costos de la receta
B4: Lista de Proveedores
B5: Capacitar al equipo

Sheet PRECIOS
A1: PRECIOS COMPRA DE PLANTA
A2: PROVEEDOR | B2: I/S | C2: PRODUCTO/INSUMO | D2: PROVEEDOR / PRECIO COMPRA | E2: PROVEEDOR / PRECIO COMPRA | F2: PROVEEDOR / PRECIO COMPRA | G2: PROVEEDOR / PRECIO COMPRA | H2: PROVEEDOR / PRECIO COMPRA | I2: PROVEEDOR / PRECIO COMPRA | J2: PROVEEDOR / PRECIO COMPRA | K2: PESO | L2: UNIDAD MEDIDA | M2: VALOR DEL GRAMO
C3: CARNES | D3: El Gran Langostino | E3: Choridanni | F3: LA 27 | G3: Supertiendas Cañaveral | H3: Cervalle | I3: Distribuidora Monos | J3: Comercializadora Malta
A4: Distribuidora Monos | C4: LOMO VICHE ESPECIAL | I4: 47900 | J4: 56000 | K4: 1000 | L4: GR | M4: =I4/K4 -> 47.9
A5: Distribuidora Monos | C5: MOLIDA CORTES FINOS X 3970 SN | I5: 21900 | K5: 1000 | L5: GR | M5: =I5/K5 -> 21.9
A6: Distribuidora Monos | C6: MOLIDA DE RES NACIONAL X 4180 SR | I6: 20500 | K6: 1000 | L6: GR | M6: =I6/K6 -> 20.5
A7: Distribuidora Monos | C7: COSTILLA DE CERDO LLANERA X 4955 | I7: 19900 | K7: 1000 | L7: GR | M7: =I7/K7 -> 19.9
A8: Distribuidora Monos | C8: TOCINETA AHUMADA COCIDA | I8: 26900 | K8: 1000 | L8: GR | M8: =I8/K8 -> 26.9
A9: Distribuidora Monos | C9: PUNTA DE ANCA URUGUAYA X 1000 GR | I9: 57900
A10: Distribuidora Monos | C10: LOMO CARACHA ANGUS URUGUAYA 1000 GR | I10: 45900.11
A11: Supertiendas Cañaveral | C11: PERNIL MCPOLLO CAMPO | G11: 9400 | J11: 8500 | K11: 1000 | L11: GR | M11: =G11/K11 -> 9.4
A12: Supertiendas Cañaveral | C12: PUNTA DE ANCA MADURADA X 1000 GR DIA | G12: 64000 | J12: 47800 | K12: 1000 | L12: GR | M12: =I12/K12 -> 0
A13: Supertiendas Cañaveral | C13: LOMO CARACHA 1000 chatA DIA | G13: 54000 | J13: 44200 | K13: 1000 | L13: GR | M13: =G13/K13 -> 54
A14: Cervalle | C14: BONDIOLA X 1000 GR | H14: 23550 | K14: 1001 | L14: GR | M14: =I14/K14 -> 0
A15: El Gran Langostino | C15: PULPO GRD X1000 | D15: 63500 | K15: 1000 | L15: GR | M15: =D15/K15 -> 63.5
A16: Choridanni | C16: CHORIZO PARRILLERO X 5 | E16: 13450 | K16: 5 | L16: GR | M16: =I16/K16 -> 0
A17: Porcicarnes | C17: CHICHARON BARRIGUERO X 1000 | I17: 33270 | J17: 25400 | K17: 1000 | L17: GR | M17: =J17/K17 -> 25.4
A18: La 27 | C18: TOCINETA ARTESANAL X 1000 GR | F18: 23000 | K18: 1000 | L18: GR | M18: =I18/K18 -> 0
A19: La 27 | C19: JAMON CALIMA 500 GR | F19: 5238.1 | K19: 500 | L19: GR | M19: =I19/K19 -> 0
C22: LACTEOS | D22: LA 27 | E22: Quesos Don Luis | F22: Mercar
C23: QUESO COSTEÑO | E23: 11000
C24: QUESO MOZARELLA X 2500 | D24: 48800 | E24: 54000 | K24: 2500 | L24: GR | M24: =I24/K24 -> 0
C25: QUESO TAJADO SANT ELENA X 2500 GR | D25: 48800 | E25: 53000
C26: CREMA DE LECHE X 850 ML | F26: 17950 | K26: 850 | L26: GR | M26: =F26/K26 -> 21.117647
C27: LECHERA X 2000 ML | E27: 27000 | K27: 2000 | L27: ML | M27: =E27/K27 -> 13.5
C28: PAPAS | D28: Supertiendas Cañaveral | E28: Distribuidora Monos
A29: Supertiendas Cañaveral | C29: PAPA AMARILLA | D29: 4200 | K29: 1000 | L29: GR | M29: =I29/K29 -> 0
A30: Distribuidora Monos | C30: PAPAS A LA FRANCESA X 3000 | E30: 20500 | K30: 3000 | L30: GR | M30: =J30/K30 -> 0
C31: PAN | D31: LA 27 | E31: Distribuidora Monos | F31: D1 | G31: Pan Wich
C32: PAN HAMBURGUESA GOURMET AJONJ X 8 | E32: 8400 | K32: 8 | L32: UND | M32: =I32/K32 -> 0
A33: Distribuidora Monos | C33: PAN HAMBURGUESA LISO BRIOCHE X 8 | E33: 8400 | K33: 8 | L33: UND | M33: =I33/K33 -> 0
C34: PAN HAMBURGUESA X 10 | G34: 7800
A35: La 27 | C35: PAN TAJADO BIMBO | D35: 6500 | F35: 3250 | K35: 1 | L35: PAQ | M35: =I35/K35 -> 0
C36: BEBIDAS Y LICORES | D36: Licores Palmira | E36: Empresarial Giraldo | M36: =I36/K36 -> #DIV/0!
A37: Licores palmira | C37: VINO CATA TINTO X 1000 | D37: 20500 | E37: 19399 | K37: 1000 | L37: ML | M37: =I37/K37 -> 0
A38: Licores palmira | C38: TEQUILA JOSE CUERVO X 700 | D38: 69900 | E38: 79900 | K38: 700 | L38: ML | M38: =I38/K38 -> 0
A39: Licores palmira | C39: TEQUILA OLMECA X 700 | D39: 73400 | K39: 700 | L39: ML | M39: =I39/K39 -> 0
C40: VODKA ADSOLUT BLUE X 700 ML | E40: 77000
A41: Licores palmira | C41: MARTINI ROSSO X 750 | D41: 63800 | K41: 750 | L41: ML | M41: =I41/K41 -> 0
A42: Licores palmira | C42: AGUARDIENTE BLANCO TR X 750 | D42: 39500 | E42: 39100 | K42: 750 | L42: ML | M42: =I42/K42 -> 0
...

Sheet LISTADO  PRODUCTO
A1: Item | B1: GRUPO | C1: PRODUCTO | D1: Costo ing + Variacion | E1: % Ingredientes + Variacion | F1: Costo EMPAQ | G1: Costo Ing+emp | H1: % Costo Ing + emp | I1: Costo todo con Combo | J1: Precio de venta | K1: precio sin impuesto al consumo | L1: PRECIO DE VENTAS | M1: MARGEN CONTRIBUCION SIN EMP | N1: % CONTRIBUCION SIN EMP | O1: MARGEN CONTRIBUCION + EMP | P1: % CONTRIBUCION + EMP | Q1: PRECIO ACTUAL COMBO | R1: PRECIO PROVIASIONAL COMBO | S1: DIFERENCIA | T1: NUEVO NOMBRE
A2: 1 | B2: CORTES | C2: CHURRASCO | D2: ='CORTES '!F15 -> 23010.9 | E2: =D2/K2 -> 0.4518504 | F2: 0 | G2: =+D2+F2 -> 23010.9 | H2: =G2/K2 -> 0.4518504 | I2: =+D2+F2+H2 -> 23011.352 | J2: ='CORTES '!F16 -> 55000 | K2: =+J2/1.08 -> 50925.926 | L2: =J2 -> 55000 | M2: 0 | N2: =M2/K2 -> 0 | O2: 0 | P2: =O2/K2 -> 0 | Q2: =#REF! -> #REF! | R2: 0
A3: 2 | B3: CORTES | C3: PUNTA DE ANCA | D3: ='CORTES '!L15 -> 33005.5 | E3: =D3/K3 -> 0.7129188 | F3: 0 | G3: =+D3+F3 -> 33005.5 | H3: =G3/K3 -> 0.7129188 | I3: =+D3+F3+H3 -> 33006.213 | J3: ='CORTES '!L16 -> 50000 | K3: =+J3/1.08 -> 46296.296 | L3: =J3 -> 50000 | M3: 0 | N3: =M3/K3 -> 0 | O3: 0 | P3: =O3/K3 -> 0 | Q3: =#REF! -> #REF! | R3: 0
A4: 3 | B4: CORTES | C4: BEBY BEEF | D4: ='CORTES '!R15 -> 20300.5 | E4: =D4/K4 -> 0.34257094 | F4: 0 | G4: =+D4+F4 -> 20300.5 | H4: =G4/K4 -> 0.34257094 | I4: =+D4+F4+H4 -> 20300.843 | J4: ='CORTES '!R16 -> 64000 | K4: =+J4/1.08 -> 59259.259 | L4: =J4 -> 64000 | M4: 0 | N4: =M4/K4 -> 0 | O4: 0 | P4: =O4/K4 -> 0 | Q4: =#REF! -> #REF! | R4: 0
A5: 4 | B5: PICADAS | C5: PICADA MALAGANA X 4 | D5: ='PICADA MALAGANA'!G27 -> 31377.115 | E5: =D5/K5 -> 0.24205203 | F5: 0 | G5: =+D5+F5 -> 31377.115 | H5: =G5/K5 -> 0.24205203 | I5: =+D5+F5+H5 -> 31377.357 | J5: ='PICADA MALAGANA'!G34 -> 140000 | K5: =+J5/1.08 -> 129629.63 | L5: =J5 -> 140000 | M5: 0 | N5: =M5/K5 -> 0 | O5: 0 | P5: =O5/K5 -> 0 | Q5: =#REF! -> #REF! | R5: 0
A6: 5 | B6: PICADAS | C6: PICADA MALAGANA X 2 | D6: ='PICADA MALAGANA'!G60 -> 18306.365 | E6: =D6/K6 -> 0.23259852 | F6: 0 | G6: =+D6+F6 -> 18306.365 | H6: =G6/K6 -> 0.23259852 | I6: =+D6+F6+H6 -> 18306.598 | J6: ='PICADA MALAGANA'!G66 -> 85000 | K6: =+J6/1.08 -> 78703.704 | L6: =J6 -> 85000 | M6: 0 | N6: =M6/K6 -> 0 | O6: 0 | P6: =O6/K6 -> 0 | Q6: =#REF! -> #REF! | R6: 0
A7: 6 | B7: ENTRADAS | C7: CHORIZO PARRILLERO | D7: ='ENTRADAS (2)'!L20 -> 8443.93 | E7: =D7/K7 -> 0.36477778 | F7: 0 | G7: =+D7+F7 -> 8443.93 | H7: =G7/K7 -> 0.36477778 | I7: =+D7+F7+H7 -> 8444.2948 | J7: ='ENTRADAS (2)'!L21 -> 25000 | K7: =+J7/1.08 -> 23148.148 | L7: =J7 -> 25000 | M7: 0 | N7: =M7/K7 -> 0 | O7: 0 | P7: =O7/K7 -> 0 | Q7: =#REF! -> #REF! | R7: 0
A8: 7 | B8: ENTRADAS | C8: ENSALADA FRESCA | D8: ='ENTRADAS (2)'!R20 -> 2423.333 | E8: =D8/K8 -> 0.4026461 | F8: 0 | G8: =+D8+F8 -> 2423.333 | H8: =G8/K8 -> 0.4026461 | I8: =+D8+F8+H8 -> 2423.7356 | J8: ='ENTRADAS (2)'!R21 -> 6500 | K8: =+J8/1.08 -> 6018.5185 | L8: =J8 -> 6500 | M8: 0 | N8: =M8/K8 -> 0 | O8: 0 | P8: =O8/K8 -> 0 | Q8: =#REF! -> #REF! | R8: 0
A9: 8 | B9: ENTRADAS | C9: ABORRAJADOS | D9: ='ENTRADAS (2)'!F20 -> 6600 | E9: =D9/K9 -> 0.28512 | F9: 0 | G9: =+D9+F9 -> 6600 | H9: =G9/K9 -> 0.28512 | I9: =+D9+F9+H9 -> 6600.2851 | J9: ='ENTRADAS (2)'!F21 -> 25000 | K9: =+J9/1.08 -> 23148.148 | L9: =J9 -> 25000 | M9: 0 | N9: =M9/K9 -> 0 | O9: 0 | P9: =O9/K9 -> 0 | Q9: =#REF! -> #REF! | R9: 0
A10: 9 | B10: ENTRADAS | C10: SALPICON DE PULPÓ Y CHICHARON | D10: ='ENTRADAS (2)'!X20 -> 5704.6 | E10: =D10/K10 -> 0.16651265 | F10: 0 | G10: =+D10+F10 -> 5704.6 | H10: =G10/K10 -> 0.16651265 | I10: =+D10+F10+H10 -> 5704.7665 | J10: ='ENTRADAS (2)'!X21 -> 37000 | K10: =+J10/1.08 -> 34259.259 | L10: =J10 -> 37000 | M10: 0 | N10: =M10/K10 -> 0 | O10: 0 | P10: =O10/K10 -> 0 | Q10: =#REF! -> #REF! | R10: 0
A11: 10 | B11: ENTRADAS | C11: CARPACCIO DE BONDIOLA ACARAMELADA | D11: ='ENTRADAS (2)'!F42 -> 2939.2 | E11: =D11/K11 -> 0.1058112 | F11: 0 | G11: =+D11+F11 -> 2939.2 | H11: =G11/K11 -> 0.1058112 | I11: =+D11+F11+H11 -> 2939.3058 | J11: ='ENTRADAS (2)'!F43 -> 30000 | K11: =+J11/1.08 -> 27777.778 | L11: =J11 -> 30000 | M11: 0 | N11: =M11/K11 -> 0 | O11: 0 | P11: =O11/K11 -> 0 | Q11: =#REF! -> #REF! | R11: 0
A12: 11 | B12: ALMUERZOS | C12: BONDIOLA DE CERDO | D12: ='ALMUERZOS Y CREMAS '!AD21 -> 12276.87 | E12: =D12/K12 -> 0.51193126 | F12: ='ALMUERZOS Y CREMAS '!AD19 -> 1740 | G12: =+D12+F12 -> 14016.87 | H12: =G12/K12 -> 0.58448724 | I12: =+D12+F12+H12 -> 14017.454 | J12: ='ALMUERZOS Y CREMAS '!AD24 -> 25900 | K12: =+J12/1.08 -> 23981.481 | L12: =J12 -> 25900 | M12: =K12-D12 -> 11704.611 | N12: =M12/K12 -> 0.48806874 | O12: =K12-G12 -> 9964.6115 | P12: =O12/K12 -> 0.41551276 | Q12: =#REF! -> #REF! | R12: 0
A13: 12 | B13: ALMUERZOS | C13: FILETE TILAPIA | D13: ='ALMUERZOS Y CREMAS '!X22 -> 13935.74 | E13: =D13/K13 -> 0.539448 | F13: ='ALMUERZOS Y CREMAS '!X20 -> 1740 | G13: =+D13+F13 -> 15675.74 | H13: =G13/K13 -> 0.60680284 | I13: =+D13+F13+H13 -> 15676.347 | J13: ='ALMUERZOS Y CREMAS '!X25 -> 27900 | K13: =+J13/1.08 -> 25833.333 | L13: =J13 -> 27900 | M13: =K13-D13 -> 11897.593 | N13: =M13/K13 -> 0.460552 | O13: =K13-G13 -> 10157.593 | P13: =O13/K13 -> 0.39319716 | Q13: =#REF! -> #REF! | R13: 0
A14: 13 | B14: ALMUERZOS | C14: CADERITA SALSA DE CHAMPIÑON | D14: ='ALMUERZOS Y CREMAS '!R22 -> 14558.47 | E14: =D14/K14 -> 0.56355368 | F14: ='ALMUERZOS Y CREMAS '!R20 -> 1740 | G14: =+D14+F14 -> 16298.47 | H14: =G14/K14 -> 0.63090852 | I14: =+D14+F14+H14 -> 16299.101 | J14: ='ALMUERZOS Y CREMAS '!R25 -> 27900 | K14: =+J14/1.08 -> 25833.333 | L14: =J14 -> 27900 | M14: =K14-D14 -> 11274.863 | N14: =M14/K14 -> 0.43644632 | O14: =K14-G14 -> 9534.8633 | P14: =O14/K14 -> 0.36909148 | Q14: =#REF! -> #REF! | R14: 0
A15: 14 | B15: ALMUERZOS | C15: CUBITOS DE POLLO SALSA CILANTRO | D15: ='ALMUERZOS Y CREMAS '!L21 -> 12884.34 | E15: =D15/K15 -> 0.55883884 | F15: ='ALMUERZOS Y CREMAS '!L19 -> 1740 | G15: =+D15+F15 -> 14624.34 | H15: =G15/K15 -> 0.63430872 | I15: =+D15+F15+H15 -> 14624.974 | J15: ='ALMUERZOS Y CREMAS '!L24 -> 24900 | K15: =+J15/1.08 -> 23055.556 | L15: =J15 -> 24900 | M15: =K15-D15 -> 10171.216 | N15: =M15/K15 -> 0.44116116 | O15: =K15-G15 -> 8431.2156 | P15: =O15/K15 -> 0.36569128 | Q15: =#REF! -> #REF! | R15: 0
A16: 15 | B16: ALMUERZOS | C16: MILANESA DE CERDO | D16: ='ALMUERZOS Y CREMAS '!F22 -> 14659.47 | E16: =D16/K16 -> 0.56746335 | F16: ='ALMUERZOS Y CREMAS '!F20 -> 1740 | G16: =+D16+F16 -> 16399.47 | H16: =G16/K16 -> 0.63481819 | I16: =+D16+F16+H16 -> 16400.105 | J16: ='ALMUERZOS Y CREMAS '!F25 -> 27900 | K16: =+J16/1.08 -> 25833.333 | L16: =J16 -> 27900 | M16: =K16-D16 -> 11173.863 | N16: =M16/K16 -> 0.43253665 | O16: =K16-G16 -> 9433.8633 | P16: =O16/K16 -> 0.36518181 | Q16: =#REF! -> #REF! | R16: 0
A17: 16 | B17: ALMUERZOS | D17: =#REF! -> #REF! | E17: =D17/K17 -> #REF! | F17: 0 | G17: =+D17+F17 -> #REF! | H17: =G17/K17 -> #REF! | I17: =+D17+F17+H17 -> #REF! | J17: =#REF! -> #REF! | K17: =+J17/1.08 -> #REF! | L17: =J17 -> #REF! | M17: 0 | N17: =M17/K17 -> #REF! | O17: 0 | P17: =O17/K17 -> #REF! | Q17: =#REF! -> #REF! | R17: 0
A18: 17 | B18: PIZZAS | C18: MARGARITA | D18: =PIZZAS!R17 -> 12799.6 | E18: =D18/K18 -> 0.4607856 | F18: 0 | G18: =+D18+F18 -> 12799.6 | H18: =G18/K18 -> 0.4607856 | I18: =+D18+F18+H18 -> 12800.061 | J18: =PIZZAS!R18 -> 30000 | K18: =+J18/1.08 -> 27777.778 | L18: =J18 -> 30000 | M18: =K18-D18 -> 14978.178 | N18: =M18/K18 -> 0.5392144 | O18: =K18-G18 -> 14978.178 | P18: =O18/K18 -> 0.5392144 | Q18: =#REF! -> #REF! | R18: 0
A19: 18 | B19: PIZZAS | C19: SAMBA | D19: =PIZZAS!X17 -> 15083.64 | E19: =D19/K19 -> 0.50907285 | F19: 0 | G19: =+D19+F19 -> 15083.64 | H19: =G19/K19 -> 0.50907285 | J19: =PIZZAS!X18 -> 32000 | K19: =+J19/1.08 -> 29629.63 | L19: =J19 -> 32000 | M19: =K19-D19 -> 14545.99 | N19: =M19/K19 -> 0.49092715 | O19: =K19-G19 -> 14545.99 | P19: =O19/K19 -> 0.49092715 | Q19: =#REF! -> #REF! | R19: 0
A20: 19 | B20: PIZZAS | C20: ORIGEN | D20: =PIZZAS!AD17 -> 20785.831 | E20: =D20/K20 -> 0.56121744 | F20: 0 | G20: =+D20+F20 -> 20785.831 | H20: =G20/K20 -> 0.56121744 | J20: 40000 | K20: =+J20/1.08 -> 37037.037 | L20: =J20 -> 40000 | M20: =K20-D20 -> 16251.206 | N20: =M20/K20 -> 0.43878256 | O20: =K20-G20 -> 16251.206 | P20: =O20/K20 -> 0.43878256 | Q20: =#REF! -> #REF! | R20: 0
A21: 20 | B21: PIZZAS | C21: CARNES | D21: =PIZZAS!L17 -> 9971.5 | E21: =D21/K21 -> 0.28340053 | F21: =PIZZAS!L13 -> 1800 | G21: =+D21+F21 -> 11771.5 | H21: =G21/K21 -> 0.33455842 | I21: =+D21+F21+H21 -> 11771.835 | J21: =PIZZAS!L18 -> 38000 | K21: =+J21/1.08 -> 35185.185 | L21: =J21 -> 38000 | M21: =K21-D21 -> 25213.685 | N21: =M21/K21 -> 0.71659947 | O21: =K21-G21 -> 23413.685 | P21: =O21/K21 -> 0.66544158 | Q21: =#REF! -> #REF! | R21: 0
A22: 21 | B22: PASTAS | C22: CARBONARA | D22: =PASTAS!F20 -> 5161.497 | E22: =D22/K22 -> 0.18581389 | F22: 0 | G22: =+D22+F22 -> 5161.497 | H22: =G22/K22 -> 0.18581389 | J22: =PASTAS!F21 -> 30000 | K22: =+J22/1.08 -> 27777.778 | L22: =J22 -> 30000 | M22: =K22-D22 -> 22616.281 | N22: =M22/K22 -> 0.81418611 | O22: =K22-G22 -> 22616.281 | P22: =O22/K22 -> 0.81418611 | Q22: =#REF! -> #REF! | R22: 0
A23: 22 | B23: PASTAS | C23: NAPOLITANA | D23: =PASTAS!L20 -> 3912.997 | E23: =D23/K23 -> 0.15092988 | F23: 0 | G23: =+D23+F23 -> 3912.997 | H23: =G23/K23 -> 0.15092988 | J23: =PASTAS!L21 -> 28000 | K23: =+J23/1.08 -> 25925.926 | L23: =J23 -> 28000 | M23: =K23-D23 -> 22012.929 | N23: =M23/K23 -> 0.84907012 | O23: =K23-G23 -> 22012.929 | P23: =O23/K23 -> 0.84907012 | Q23: =#REF! -> #REF! | R23: 0
A24: 23 | B24: PASTAS | C24: AMATRICIANA | D24: =PASTAS!R20 -> 4544.705 | E24: =D24/K24 -> 0.16360938 | F24: 0 | G24: =+D24+F24 -> 4544.705 | H24: =G24/K24 -> 0.16360938 | J24: =PASTAS!R21 -> 30000 | K24: =+J24/1.08 -> 27777.778 | L24: =J24 -> 30000 | M24: =K24-D24 -> 23233.073 | N24: =M24/K24 -> 0.83639062 | O24: =K24-G24 -> 23233.073 | P24: =O24/K24 -> 0.83639062 | Q24: =#REF! -> #REF! | R24: 0
A25: 24 | B25: POSTRES | C25: CARLOTTA DE LIMON | D25: =POSTRES!F22 -> 4431.2033 | E25: =D25/K25 -> 0.3009874 | F25: 0 | G25: =+D25+F25 -> 4431.2033 | H25: =G25/K25 -> 0.3009874 | J25: =POSTRES!F21 -> 15900 | K25: =+J25/1.08 -> 14722.222 | L25: =J25 -> 15900 | M25: =K25-D25 -> 10291.019 | N25: =M25/K25 -> 0.6990126 | O25: =K25-G25 -> 10291.019 | P25: =O25/K25 -> 0.6990126 | Q25: =#REF! -> #REF! | R25: 0
A26: 25 | B26: POSTRES | C26: FLAN NAPOLITANO | D26: =POSTRES!L22 -> 2563.1788 | E26: =D26/K26 -> 0.2796195 | F26: 0 | G26: =+D26+F26 -> 2563.1788 | H26: =G26/K26 -> 0.2796195 | J26: =POSTRES!L21 -> 9900 | K26: =+J26/1.08 -> 9166.6667 | L26: =J26 -> 9900 | M26: =K26-D26 -> 6603.4879 | N26: =M26/K26 -> 0.7203805 | O26: =K26-G26 -> 6603.4879 | P26: =O26/K26 -> 0.7203805 | Q26: =#REF! -> #REF! | R26: 0
A27: 26 | B27: PLATOS | C27: CHICHARON ORNEADO | D27: =PLATOS!F20 -> 13773.32 | E27: =D27/K27 -> 0.31649331 | F27: =PLATOS!F16 -> 1740 | G27: =+D27+F27 -> 15513.32 | H27: =G27/K27 -> 0.35647629 | J27: =PLATOS!F21 -> 47000 | K27: =+J27/1.08 -> 43518.519 | L27: =J27 -> 47000 | M27: =K27-D27 -> 29745.199 | N27: =M27/K27 -> 0.68350669 | O27: =K27-G27 -> 28005.199 | P27: =O27/K27 -> 0.64352371 | Q27: =#REF! -> #REF! | R27: 0
A28: 27 | B28: PLATOS | C28: POLLO DORADO | D28: =PLATOS!L20 -> 11847 | E28: =D28/K28 -> 0.27222894 | F28: =PLATOS!L16 -> 1740 | G28: =+D28+F28 -> 13587 | H28: =G28/K28 -> 0.31221191 | J28: =PLATOS!L21 -> 47000 | K28: =+J28/1.08 -> 43518.519 | L28: =J28 -> 47000 | M28: =K28-D28 -> 31671.519 | N28: =M28/K28 -> 0.72777106 | O28: =K28-G28 -> 29931.519 | P28: =O28/K28 -> 0.68778809 | Q28: =#REF! -> #REF! | R28: 0
A29: 28 | B29: PLATOS | C29: ENSALADA DE BONDIOLA | D29: =PLATOS!R21 -> 10435.7 | E29: =D29/K29 -> 0.2817639 | F29: =PLATOS!L17 -> 0 | G29: =+D29+F29 -> 10435.7 | H29: =G29/K29 -> 0.2817639 | J29: =PLATOS!R22 -> 40000 | K29: =+J29/1.08 -> 37037.037 | L29: =J29 -> 40000 | M29: =K29-D29 -> 26601.337 | N29: =M29/K29 -> 0.7182361 | O29: =K29-G29 -> 26601.337 | P29: =O29/K29 -> 0.7182361 | Q29: =#REF! -> #REF! | R29: 0
A30: 29 | B30: PLATOS | C30: COSTILLA SOUS VIDE | D30: =PLATOS!F43 -> 17096.2 | E30: =D30/K30 -> 0.3357072 | F30: =PLATOS!F39 -> 1740 | G30: =+D30+F30 -> 18836.2 | H30: =G30/K30 -> 0.36987447 | J30: =PLATOS!F44 -> 55000 | K30: =+J30/1.08 -> 50925.926 | L30: =J30 -> 55000 | M30: =K30-D30 -> 33829.726 | N30: =M30/K30 -> 0.6642928 | O30: =K30-G30 -> 32089.726 | P30: =O30/K30 -> 0.63012553 | Q30: =#REF! -> #REF! | R30: 0
A31: 30 | B31: TARDEO | C31: PANCHO | D31: =TARDEO!F20 -> 6625.85 | E31: =D31/K31 -> 0.45005774 | F31: =PLATOS!F40 -> 0 | G31: =+D31+F31 -> 6625.85 | H31: =G31/K31 -> 0.45005774 | J31: =TARDEO!F21 -> 15900 | K31: =+J31/1.08 -> 14722.222 | L31: =J31 -> 15900 | M31: =K31-D31 -> 8096.3722 | N31: =M31/K31 -> 0.54994226 | O31: =K31-G31 -> 8096.3722 | P31: =O31/K31 -> 0.54994226 | Q31: =#REF! -> #REF! | R31: 0
A32: 31 | B32: TARDEO | C32: WRAPP | D32: =TARDEO!L20 -> 2962.08 | E32: =D32/K32 -> 0.2934905 | F32: 0 | G32: =+D32+F32 -> 2962.08 | H32: =G32/K32 -> 0.2934905 | J32: =TARDEO!L21 -> 10900 | K32: =+J32/1.08 -> 10092.593 | L32: =J32 -> 10900 | M32: =K32-D32 -> 7130.5126 | N32: =M32/K32 -> 0.7065095 | O32: =K32-G32 -> 7130.5126 | P32: =O32/K32 -> 0.7065095 | Q32: =#REF! -> #REF! | R32: 0
A33: 32 | B33: TARDEO | C33: COLOSO /PALMEÑO | D33: =TARDEO!R20 -> 5568.2 | E33: =D33/K33 -> 0.35583763 | F33: 0 | G33: =+D33+F33 -> 5568.2 | H33: =G33/K33 -> 0.35583763 | J33: =TARDEO!R21 -> 16900 | K33: =+J33/1.08 -> 15648.148 | L33: =J33 -> 16900 | M33: =K33-D33 -> 10079.948 | N33: =M33/K33 -> 0.64416237 | O33: =K33-G33 -> 10079.948 | P33: =O33/K33 -> 0.64416237 | Q33: =#REF! -> #REF! | R33: 0
A34: 33 | B34: ARROCES | C34: ARROZ CON POLLO | D34: =ARROCES!F20 -> 4565.924 | E34: =D34/K34 -> 0.29178686 | F34: 0 | G34: =+D34+F34 -> 4565.924 | H34: =G34/K34 -> 0.29178686 | J34: =ARROCES!F21 -> 16900 | K34: =+J34/1.08 -> 15648.148 | L34: =J34 -> 16900 | M34: =K34-D34 -> 11082.224 | N34: =M34/K34 -> 0.70821314 | O34: =K34-G34 -> 11082.224 | P34: =O34/K34 -> 0.70821314 | Q34: =#REF! -> #REF! | R34: 0
A35: 34 | B35: ARROCES | C35: ARROZ MIXTO | D35: =ARROCES!L20 -> 5863.924 | E35: =D35/K35 -> 0.353801 | F35: 0 | G35: =+D35+F35 -> 5863.924 | H35: =G35/K35 -> 0.353801 | J35: =ARROCES!L21 -> 17900 | K35: =+J35/1.08 -> 16574.074 | L35: =J35 -> 17900 | M35: =K35-D35 -> 10710.15 | N35: =M35/K35 -> 0.646199 | O35: =K35-G35 -> 10710.15 | P35: =O35/K35 -> 0.646199 | Q35: =#REF! -> #REF! | R35: 0
A36: 35 | B36: ARROCES | C36: ARROZ CON CAMARON | D36: 0
A37: 36 | B37: NAVIDEÑO | C37: LOMO DE CERDO AL HORNO | D37: ='CENAS DICIEMBRE '!L23 -> 16572.6 | E37: =D37/K37 -> 0.35796816 | F37: 0 | G37: =+D37+F37 -> 16572.6 | H37: =G37/K37 -> 0.35796816 | J37: ='CENAS DICIEMBRE '!L24 -> 50000 | K37: =+J37/1.08 -> 46296.296 | L37: =J37 -> 50000 | M37: =K37-D37 -> 29723.696 | N37: =M37/K37 -> 0.64203184 | O37: =K37-G37 -> 29723.696 | P37: =O37/K37 -> 0.64203184 | Q37: =#REF! -> #REF!
C38: PAQUETE NAVIDAD | D38: ='CENAS DICIEMBRE '!U8 -> 30549 | E38: =D38/K38 -> 0.366588 | F38: 0 | G38: =+D38+F38 -> 30549 | H38: =G38/K38 -> 0.366588 | J38: ='CENAS DICIEMBRE '!V8 -> 90000 | K38: =+J38/1.08 -> 83333.333 | L38: =J38 -> 90000 | M38: =K38-D38 -> 52784.333 | N38: =M38/K38 -> 0.633412 | O38: =K38-G38 -> 52784.333 | P38: =O38/K38 -> 0.633412 | Q38: =#REF! -> #REF!
D39: 0 | E39: =+#REF!/B39 -> #REF! | F39: 0 | G39: =+D39+F39 -> 0 | H39: =+#REF!/E39 -> #REF! | I39: =+D39+F39+H39 -> #REF! | J39: =#REF! -> #REF! | K39: =+J39/1.08 -> #REF! | L39: =J39 -> #REF! | M39: 0 | O39: 0 | Q39: =#REF! -> #REF! | R39: 0

Sheet CENAS DICIEMBRE 
B2: LOMO DE RES RELLENO | H2: LOMO DE CERDO AL HORNO | N2: PLATO NAVIDEÑO
B3: INGREDIENTES | C3: CANTIDAD | D3: UND MEDIDA | E3: COS/GR | F3: VALOR | H3: INGREDIENTES | I3: CANTIDAD | J3: UND MEDIDA | K3: COS/GR | L3: VALOR | N3: INGREDIENTES | O3: CANTIDAD | P3: UND MEDIDA | Q3: COS/GR | R3: VALOR | T3: Reserva para 80 personas | U3: Costo | V3: Precio venta | W3: Utilidad
B4: LOMO DE RES (REDONDO) | C4: 670 | D4: GR | E4: 50.3 | F4: =C4*E4 -> 33701 | H4: LOMO DE CERDO | I4: 250 | J4: GR | K4: 22.08 | L4: =I4*K4 -> 5520 | N4: MANJAR BLANCO | O4: 40 | P4: GR | Q4: 40 | R4: =O4*Q4 -> 1600 | T4: Churrasco 350 gr | U4: 20919
B5: ACETIE DE OLIVA | C5: 20 | D5: GR | E5: 38.8 | F5: =C5*E5 -> 776 | H5: AJO PICADO | I5: 5 | J5: GR | K5: 15 | L5: =I5*K5 -> 75 | N5: DES AMARGADO | O5: 35 | P5: GR | Q5: 48 | R5: =O5*Q5 -> 1680 | T5: Limonada | U5: 1000
B6: TOCINETA | C6: 50 | D6: GR | E6: 26.9 | F6: =C6*E6 -> 1345 | H6: ACEITE SOYA | I6: 165 | J6: GR | K6: 38.8 | L6: =I6*K6 -> 6402 | N6: HOJALDRA | O6: 0.5 | P6: UND | Q6: 700 | R6: =O6*Q6 -> 350 | T6: Aborrajados 2 | U6: 4000
B7: CHAMPIÑON | C7: 170 | D7: GR | E7: 34.4 | F7: =C7*E7 -> 5848 | H7: SAL MARINA | I7: 4 | J7: GR | K7: 5 | L7: =I7*K7 -> 20 | N7: NATILLA | O7: 1 | P7: UND | Q7: 1000 | R7: =O7*Q7 -> 1000 | T7: Plato Navideño | U7: 4630
B8: CEBOLLA CABEZONA | C8: 65 | D8: GR | E8: 3.8 | F8: =C8*E8 -> 247 | H8: PEREJIL FRESCO | I8: 15 | J8: GR | K8: 5 | L8: =I8*K8 -> 75 | P8: GR | R8: =O8*Q8 -> 0 | U8: =SUM(U4:U7) -> 30549 | V8: 90000 | W8: =V8-U8 -> 59451
B9: SAL MARINA | C9: 4 | D9: GR | E9: 4.8 | F9: =C9*E9 -> 19.2 | H9: CREMOSO DE PAPA | I9: 200 | J9: GR | K9: 7.52 | L9: =I9*K9 -> 1504 | P9: GR | R9: =O9*Q9 -> 0 | U9: 80 | V9: 80
B10: PIMIENTA NEGRA | C10: 0.5 | D10: GR | E10: 52 | F10: =C10*E10 -> 26 | H10: SALSA FRUTOS AMARILLOS | I10: 120 | J10: GR | K10: 8.5 | L10: =I10*K10 -> 1020 | P10: GR | R10: =O10*Q10 -> 0 | U10: =U8*U9 -> 2443920 | V10: =V8*V9 -> 7200000 | W10: =V10-U10 -> 4756080
B11: AJO PICADO | C11: 5 | D11: GR | E11: 15 | F11: =C11*E11 -> 75 | H11: ARROZ BLANCO | I11: 100 | J11: GR | K11: 4.5 | L11: =I11*K11 -> 450 | R11: =O11*Q11 -> 0
B12: PEREJIL FRESCO | C12: 15 | D12: GR | E12: 5 | F12: =C12*E12 -> 75 | T12: Punta 350 gr | U12: 30005
T13: Limonada | U13: 900
B14: TOTAL | F14: =SUM(F4:F13) -> 42112.2 | H14: TOTAL | L14: =SUM(L4:L13) -> 15066 | R14: =SUM(R4:R13) -> 4630 | T14: Aborrajados 2 | U14: 4000
B15: MATERIAL DE EMPAQUE | H15: MATERIAL DE EMPAQUE | N15: MATERIAL DE EMPAQUE | T15: Plato Navideño | U15: 4630
F16: =C16*140 -> 0 | L16: =I16*140 -> 0 | N16: VINO | O16: 3000 | P16: ML | Q16: 22.6 | R16: =O16*Q16 -> 67800 | U16: =SUM(U12:U15) -> 39535 | V16: 90000 | W16: =V16-U16 -> 50465
F17: =C17*140 -> 0 | L17: =I17*140 -> 0 | N17: SODA | O17: 1500 | P17: ML | Q17: 3.28 | R17: =O17*Q17 -> 4920 | U17: 80 | V17: 80
F18: =C18*140 -> 0 | L18: =I18*140 -> 0 | N18: CANADA DRY | O18: 1500 | P18: ML | Q18: 4.27 | R18: =O18*Q18 -> 6405 | U18: =U16*U17 -> 3162800 | V18: =V16*V17 -> 7200000 | W18: =V18-U18 -> 4037200
B19: TOTAL | F19: =SUM(F16:F18) -> 0 | H19: TOTAL | L19: =SUM(L16:L18) -> 0 | R19: =SUM(R16:R18) -> 79125 | S19: =R19/20 -> 3956.25
B20: COSTO + PRECIO DE VENTA | H20: COSTO + PRECIO DE VENTA | N20: COSTO + PRECIO DE VENTA | T20: Cervezas | U20: Costo Und | V20: Costo total | W20: Precio venta | X20: Utilidad | Z20: Precio venta | AA20: Utilidad
B21: COSTO DE INGREDIENTES | F21: =F14+F19 -> 42112.2 | H21: COSTO DE INGREDIENTES | L21: =L14+L19 -> 15066 | N21: COSTO DE INGREDIENTES | R21: =R14+R19 -> 83755 | T21: Corona | U21: 3787 | V21: =U21*160 -> 605920 | W21: 8000 | X21: =W21-U21 -> 4213 | Y21: 160 | Z21: =W21*Y21 -> 1280000 | AA21: =Z21-V21 -> 674080
B22: MARGEN DE ERROR O VARIACION 10% | F22: =F21*0.1 -> 4211.22 | H22: MARGEN DE ERROR O VARIACION 10% | L22: =L21*0.1 -> 1506.6 | N22: MARGEN DE ERROR O VARIACION 10% | R22: =R21*0.1 -> 8375.5 | T22: Stella | U22: 3462 | V22: =U22*160 -> 553920 | W22: 8000 | X22: =W22-U22 -> 4538 | Y22: 160 | Z22: =W22*Y22 -> 1280000 | AA22: =Z22-V22 -> 726080
B23: COSTO TOTAL DE LA PREPARACION | F23: =SUM(F21:F22) -> 46323.42 | H23: COSTO TOTAL DE LA PREPARACION | L23: =SUM(L21:L22) -> 16572.6 | N23: COSTO TOTAL DE LA PREPARACION | R23: =SUM(R21:R22) -> 92130.5 | T23: Clud dorada | U23: 3079 | V23: =U23*160 -> 492640 | W23: 8000 | X23: =W23-U23 -> 4921 | Y23: 160 | Z23: =W23*Y23 -> 1280000 | AA23: =Z23-V23 -> 787360
B24: PRECIO DE VENTA | F24: 45000 | H24: PRECIO DE VENTA | L24: 50000 | N24: PRECIO DE VENTA | R24: 30000 | T24: Michelado | W24: 3000 | Y24: 160 | Z24: =W24*Y24 -> 480000
V25: invercion | W25: utilidad
T26: total de la venta | U26: =V18+Z23 -> 8480000 | V26: =U18+V21 -> 3768720 | W26: =U26-V26 -> 4711280
B27: CREMOSO DE PAPA | H27: SALSA DE FRUTOS AMARILLOS | N27: PASTA CARBONARA
B28: INGREDIENTES | C28: CANTIDAD | D28: UND MEDIDA | E28: COS/GR | F28: VALOR | H28: INGREDIENTES | I28: CANTIDAD | J28: UND MEDIDA | K28: COS/GR | L28: VALOR | N28: INGREDIENTES | O28: CANTIDAD | P28: UND MEDIDA | Q28: COS/GR | R28: VALOR
B29: PAPA PARDA | C29: 150 | D29: GR | E29: 3.59 | F29: =C29*E29 -> 538.5 | H29: MARACUYA | I29: 50 | J29: gr | K29: 6.9 | L29: =I29*K29 -> 345 | P29: gr | R29: =O29*Q29 -> 0
B30: CREMA DE LECHE | C30: 50 | D30: GR | E30: 16.1 | F30: =C30*E30 -> 805 | H30: JUGO DE NARANJA | I30: 20 | J30: gr | K30: 4 | L30: =I30*K30 -> 80 | P30: gr | R30: =O30*Q30 -> 0
B31: PASTA AJO | C31: 2 | D31: GR | E31: 15 | F31: =C31*E31 -> 30 | H31: UCHUVA | I31: 15 | J31: gr | K31: 23.6 | L31: =I31*K31 -> 354 | P31: gr | R31: =O31*Q31 -> 0
B32: MANTEQUILLA | C32: 5 | D32: GR | E32: 26 | F32: =C32*E32 -> 130 | H32: AZUCAR | I32: 25 | J32: gr | K32: 4 | L32: =I32*K32 -> 100 | P32: gr | R32: =O32*Q32 -> 0
F33: =C33*E33 -> 0 | H33: ANIS ESTRELLADO | I33: 2 | J33: gr | K33: 12 | L33: =I33*K33 -> 24 | P33: gr | R33: =O33*Q33 -> 0
F34: =C34*E34 -> 0 | J34: gr | L34: =I34*K34 -> 0 | P34: gr | R34: =O34*Q34 -> 0
F35: =C35*E35 -> 0 | J35: gr | L35: =I35*K35 -> 0 | P35: gr | R35: =O35*Q35 -> 0
F36: =C36*E36 -> 0 | L36: =I36*K36 -> 0 | R36: =O36*Q36 -> 0
F37: =SUM(F29:F36) -> 1503.5 | L37: =I37*K37 -> 0 | R37: =O37*Q37 -> 0
B38: MATERIAL DE EMPAQUE | H38: MATERIAL DE EMPAQUE | N38: MATERIAL DE EMPAQUE
F39: =C39*140 -> 0 | L39: =I39*140 -> 0 | R39: =O39*140 -> 0
F40: =C40*140 -> 0 | L40: =I40*140 -> 0 | R40: =O40*140 -> 0
F41: =SUM(F39:F40) -> 0 | L41: =I41*140 -> 0 | R41: =O41*140 -> 0
...

Sheet CORTES 
B2: CHURRASCO | H2: PUNTA DE ANCA | N2: BEBY BEEF
B3: INGREDIENTES | C3: CANTIDAD | D3: UND MEDIDA | E3: COS/GR | F3: VALOR | H3: INGREDIENTES | I3: CANTIDAD | J3: UND MEDIDA | K3: COS/GR | L3: VALOR | N3: INGREDIENTES | O3: CANTIDAD | P3: UND MEDIDA | Q3: COS/GR | R3: VALOR
B4: churrasco (res) | C4: 350 | D4: gr | E4: 47.04 | F4: =C4*E4 -> 16464 | H4: punta de anca | I4: 350 | J4: gr | K4: 73 | L4: =I4*K4 -> 25550 | N4: lomo viche | O4: 250 | P4: gr | Q4: 56 | R4: =O4*Q4 -> 14000
B5: Mix de papas | C5: 140 | D5: gr | E5: 5.5 | F5: =C5*E5 -> 770 | H5: ensalada | I5: 100 | J5: gr | K5: 20.71 | L5: =I5*K5 -> 2071 | N5: ensalada | O5: 100 | P5: gr | Q5: 20.71 | R5: =O5*Q5 -> 2071
B6: ensalada | C6: 100 | D6: gr | E6: 20.71 | F6: =C6*E6 -> 2071 | H6: Mix de papas | I6: 140 | J6: gr | K6: 5.5 | L6: =I6*K6 -> 770 | N6: Mix de papas | O6: 140 | P6: gr | Q6: 5.5 | R6: =O6*Q6 -> 770
B7: chimichurri argentino | C7: 60 | D7: gr | E7: 26.9 | F7: =C7*E7 -> 1614 | H7: chimichuri | I7: 60 | J7: gr | K7: 26.9 | L7: =I7*K7 -> 1614 | N7: chimichurri | O7: 60 | P7: gr | Q7: 26.9 | R7: =O7*Q7 -> 1614
B8: MATERIAL DE EMPAQUE | H8: MATERIAL DE EMPAQUE | N8: MATERIAL DE EMPAQUE
F9: =C9*140 -> 0 | L9: =I9*140 -> 0 | R9: =O9*140 -> 0
F10: =C10*140 -> 0 | L10: =I10*140 -> 0 | R10: =O10*140 -> 0
F11: =C11*140 -> 0 | L11: =I11*140 -> 0 | R11: =O11*140 -> 0
B12: COSTO + PRECIO DE VENTA | H12: COSTO + PRECIO DE VENTA | N12: COSTO + PRECIO DE VENTA
B13: COSTO DE INGREDIENTES | F13: =(F4+F5+F6+F7+F9+F10+F11) -> 20919 | H13: COSTO DE INGREDIENTES | L13: =(L4+L5+L6+L7+L9+L10+L11) -> 30005 | N13: COSTO DE INGREDIENTES | R13: =(R4+R5+R6+R7+R9+R10+R11) -> 18455
B14: MARGEN DE ERROR O VARIACION 10% | F14: =F13*0.1 -> 2091.9 | H14: MARGEN DE ERROR O VARIACION 10% | L14: =L13*0.1 -> 3000.5 | N14: MARGEN DE ERROR O VARIACION 10% | R14: =R13*0.1 -> 1845.5
B15: COSTO TOTAL DE LA PREPARACION | F15: =SUM(F13:F14) -> 23010.9 | H15: COSTO TOTAL DE LA PREPARACION | L15: =SUM(L13:L14) -> 33005.5 | N15: COSTO TOTAL DE LA PREPARACION | R15: =SUM(R13:R14) -> 20300.5
B16: PRECIO DE VENTA | F16: 55000 | H16: PRECIO DE VENTA | L16: 50000 | N16: PRECIO DE VENTA | R16: 64000
D19: malta | E19: 44000 | K19: 48000
D20: cañaveral | E20: 47040 | F20: =E20/1000 -> 47.04 | K20: 73000

Sheet TARDEO
B2: PANCHO | H2: WRAPP | N2: EL DORADO
B3: INGREDIENTES | C3: CANTIDAD | D3: UND MEDIDA | E3: COS/GR | F3: VALOR | H3: INGREDIENTES | I3: CANTIDAD | J3: UND MEDIDA | K3: COS/GR | L3: VALOR | N3: INGREDIENTES | O3: CANTIDAD | P3: UND MEDIDA | Q3: COS/GR | R3: VALOR
B4: CHORIZO | C4: 1 | D4: gr | E4: 2690 | F4: =C4*E4 -> 2690 | H4: HUEVOS | I4: 2 | J4: UND | K4: 498 | L4: =I4*K4 -> 996 | N4: COLESTLAW | O4: 80 | P4: gr | Q4: 20 | R4: =O4*Q4 -> 1600
B5: COLESTLAW | C5: 70 | D5: gr | E5: 20 | F5: =C5*E5 -> 1400 | H5: JAMON | I5: 20 | J5: gr | K5: 32.25 | L5: =I5*K5 -> 645 | N5: PAN HAMBURGUESA | O5: 1 | P5: gr | Q5: 780 | R5: =O5*Q5 -> 780
B6: LECHUGA | C6: 15 | D6: gr | E6: 20 | F6: =C6*E6 -> 300 | H6: QUESO | I6: 20 | J6: gr | K6: 21.6 | L6: =I6*K6 -> 432 | N6: PECHUGA | O6: 100 | P6: gr | Q6: 20 | R6: =O6*Q6 -> 2000
B7: PAN PERRO | C7: 1 | D7: gr | E7: 925 | F7: =C7*E7 -> 925 | H7: SAL | I7: 2 | J7: gr | K7: 2 | L7: =I7*K7 -> 4 | N7: ALIOLI CILANTRO | O7: 10 | P7: gr | Q7: 10.8 | R7: =O7*Q7 -> 108
B8: CHIMICHURRI | C8: 5 | D8: gr | E8: 26.9 | F8: =C8*E8 -> 134.5 | H8: ALBAHACA | I8: 10 | J8: gr | K8: 55.8 | L8: =I8*K8 -> 558 | N8: PAPA FRANCESA | O8: 70 | P8: gr | Q8: 8.2 | R8: =O8*Q8 -> 574
B9: PAPA FRANCESA | C9: 70 | D9: gr | E9: 8.2 | F9: =C9*E9 -> 574 | H9: TOMATE | I9: 10 | J9: gr | K9: 5.78 | L9: =I9*K9 -> 57.8 | P9: gr | R9: =O9*Q9 -> 0
D10: gr | F10: =C10*E10 -> 0 | L10: =I10*K10 -> 0 | P10: gr | R10: =O10*Q10 -> 0
F11: =C11*E11 -> 0 | L11: =I11*K11 -> 0 | R11: =O11*Q11 -> 0
F12: =SUM(F4:F11) -> 6023.5 | L12: =SUM(L4:L11) -> 2692.8 | R12: =O12*Q12 -> 0
B13: MATERIAL DE EMPAQUE | H13: MATERIAL DE EMPAQUE | N13: MATERIAL DE EMPAQUE
F14: =C14*140 -> 0 | L14: =I14*140 -> 0 | R14: =O14*140 -> 0
F15: =C15*140 -> 0 | L15: =I15*140 -> 0 | R15: =O15*140 -> 0
F16: =SUM(F14:F15) -> 0 | L16: =I16*140 -> 0 | R16: =O16*140 -> 0
B17: COSTO + PRECIO DE VENTA | H17: COSTO + PRECIO DE VENTA | N17: COSTO + PRECIO DE VENTA
B18: COSTO DE INGREDIENTES | F18: =F16+F12 -> 6023.5 | H18: COSTO DE INGREDIENTES | L18: =L12+L16 -> 2692.8 | N18: COSTO DE INGREDIENTES | R18: =(R4+R5+R6+R7+R8+R9+R10+R11+R12+R16) -> 5062
B19: MARGEN DE ERROR O VARIACION 10% | F19: =F18*0.1 -> 602.35 | H19: MARGEN DE ERROR O VARIACION 10% | L19: =L18*0.1 -> 269.28 | N19: MARGEN DE ERROR O VARIACION 10% | R19: =R18*0.1 -> 506.2
B20: COSTO TOTAL DE LA PREPARACION | F20: =SUM(F18:F19) -> 6625.85 | H20: COSTO TOTAL DE LA PREPARACION | L20: =SUM(L18:L19) -> 2962.08 | N20: COSTO TOTAL DE LA PREPARACION | R20: =SUM(R18:R19) -> 5568.2
B21: PRECIO DE VENTA | F21: 15900 | H21: PRECIO DE VENTA | L21: 10900 | N21: PRECIO DE VENTA | R21: 16900
B24: TIRAMISU | H24: COLESTLAW PARA 2 | N24: MAYONESA ARTESANAL
B25: INGREDIENTES | C25: CANTIDAD | D25: UND MEDIDA | E25: COS/GR | F25: VALOR | H25: INGREDIENTES | I25: CANTIDAD | J25: UND MEDIDA | K25: COS/GR | L25: VALOR | N25: INGREDIENTES | O25: CANTIDAD | P25: UND MEDIDA | Q25: COS/GR | R25: VALOR
B26: HUEVOS | C26: 5 | D26: gr | E26: 498 | F26: =C26*E26 -> 2490 | H26: ZANAHORIA | I26: 50 | J26: gr | K26: 4.6 | L26: =I26*K26 -> 230 | N26: HUEVO | O26: 1 | P26: gr | Q26: 498 | R26: =O26*Q26 -> 498
B27: MASCARPONE | C27: 500 | D27: gr | E27: 59.6 | F27: =C27*E27 -> 29800 | H27: REPOLLO | I27: 100 | J27: gr | K27: 11.6 | L27: =I27*K27 -> 1160 | N27: MOSTAZA | O27: 10 | P27: gr | Q27: 17.9 | R27: =O27*Q27 -> 179
B28: LICOR DE CAFÉ | C28: 56 | D28: gr | E28: 85.2 | F28: =C28*E28 -> 4771.2 | H28: PIÑA | I28: 50 | J28: gr | K28: 4.9 | L28: =I28*K28 -> 245 | N28: ACEITE SOYA | O28: 500 | P28: ML | Q28: 8.27 | R28: =O28*Q28 -> 4135
B29: EXPRESO | C29: 100 | D29: gr | E29: 50.4 | F29: =C29*E29 -> 5040 | H29: AZUCAR | I29: 30 | J29: gr | K29: 4.4 | L29: =I29*K29 -> 132 | N29: SAL | O29: 5 | P29: gr | Q29: 2 | R29: =O29*Q29 -> 10
B30: AZUCAR | C30: 220 | D30: gr | E30: 4.4 | F30: =C30*E30 -> 968 | H30: CREMA DE LECHE | I30: 20 | J30: gr | K30: 21.1 | L30: =I30*K30 -> 422 | N30: PIMIENTA | O30: 1 | P30: gr | Q30: 52 | R30: =O30*Q30 -> 52
B31: SAL | C31: 2 | D31: gr | E31: 2 | F31: =C31*E31 -> 4 | H31: LECHE CONDENSADA | I31: 20 | J31: gr | K31: 12.9 | L31: =I31*K31 -> 258 | R31: =O31*Q31 -> 0
B32: LADY FINGER | C32: 150 | D32: gr | E32: 94.3 | F32: =C32*E32 -> 14145 | H32: MAYONESA | I32: 10 | J32: gr | K32: 8.9 | L32: =I32*K32 -> 89 | R32: =O32*Q32 -> 0
B33: COCOA POLVO | C33: 20 | D33: gr | E33: 71.5 | F33: =C33*E33 -> 1430 | L33: =I33*K33 -> 0 | R33: =O33*Q33 -> 0
F34: =SUM(F26:F33) -> 58648.2 | L34: =I34*K34 -> 0 | R34: =O34*Q34 -> 0
B35: MATERIAL DE EMPAQUE | H35: MATERIAL DE EMPAQUE | N35: MATERIAL DE EMPAQUE
F36: =C36*140 -> 0 | L36: =I36*140 -> 0 | R36: =O36*140 -> 0
F37: =C37*140 -> 0 | L37: =I37*140 -> 0 | R37: =O37*140 -> 0
F38: =SUM(F36:F37) -> 0 | L38: =I38*140 -> 0 | R38: =O38*140 -> 0
B39: COSTO + PRECIO DE VENTA | H39: COSTO + PRECIO DE VENTA | N39: COSTO + PRECIO DE VENTA
B40: COSTO DE INGREDIENTES | F40: =F34+F38 -> 58648.2 | H40: COSTO DE INGREDIENTES | L40: =(L26+L27+L28+L29+L30+L31+L32+L33+L34+L38) -> 2536 | N40: COSTO DE INGREDIENTES | R40: =(R26+R27+R28+R29+R30+R31+R32+R33+R34+R38) -> 4874
B41: MARGEN DE ERROR O VARIACION 10% | F41: =F40*0.1 -> 5864.82 | H41: MARGEN DE ERROR O VARIACION 10% | L41: =L40*0.1 -> 253.6 | N41: MARGEN DE ERROR O VARIACION 10% | R41: =R40*0.1 -> 487.4
B42: COSTO TOTAL DE LA PREPARACION | F42: =SUM(F40:F41) -> 64513.02 | H42: COSTO TOTAL DE LA PREPARACION | L42: =SUM(L40:L41) -> 2789.6 | N42: COSTO TOTAL DE LA PREPARACION | R42: =SUM(R40:R41) -> 5361.4
B43: PRECIO DE VENTA | F43: 18900 | H43: PRECIO DE VENTA | L43: 0 | N43: PRECIO DE VENTA | R43: 0
...

Sheet ARROCES
B2: ARROZ POLLO | H2: ARROZ MIXTO | N2: PASTA CARBONARA
B3: INGREDIENTES | C3: CANTIDAD | D3: UND MEDIDA | E3: COS/GR | F3: VALOR | H3: INGREDIENTES | I3: CANTIDAD | J3: UND MEDIDA | K3: COS/GR | L3: VALOR | N3: INGREDIENTES | O3: CANTIDAD | P3: UND MEDIDA | Q3: COS/GR | R3: VALOR
B4: ARROZ | C4: 200 | D4: gr | E4: 4.11 | F4: =C4*E4 -> 822 | H4: ARROZ | I4: 200 | J4: gr | K4: 4.11 | L4: =I4*K4 -> 822 | P4: gr | R4: =O4*Q4 -> 0
B5: PIMENTON | C5: 12 | D5: gr | E5: 3.58 | F5: =C5*E5 -> 42.96 | H5: PIMENTON | I5: 12 | J5: gr | K5: 3.58 | L5: =I5*K5 -> 42.96 | P5: gr | R5: =O5*Q5 -> 0
B6: CEBOLLA | C6: 12 | D6: gr | E6: 3.78 | F6: =C6*E6 -> 45.36 | H6: CEBOLLA | I6: 12 | J6: gr | K6: 3.78 | L6: =I6*K6 -> 45.36 | P6: gr | R6: =O6*Q6 -> 0
B7: TOMATE | C7: 14 | D7: gr | E7: 5.78 | F7: =C7*E7 -> 80.92 | H7: TOMATE | I7: 14 | J7: gr | K7: 5.78 | L7: =I7*K7 -> 80.92 | P7: gr | R7: =O7*Q7 -> 0
B8: ALVERJAS | C8: 12 | D8: gr | E8: 23.8 | F8: =C8*E8 -> 285.6 | H8: ALVERJAS | I8: 12 | J8: gr | K8: 23.8 | L8: =I8*K8 -> 285.6 | P8: gr | R8: =O8*Q8 -> 0
B9: GUISO | C9: 20 | D9: gr | E9: 10 | F9: =C9*E9 -> 200 | H9: GUISO | I9: 20 | J9: gr | K9: 10 | L9: =I9*K9 -> 200 | P9: gr | R9: =O9*Q9 -> 0
B10: POLLO | C10: 100 | D10: gr | E10: 21 | F10: =C10*E10 -> 2100 | H10: CHORIZO | I10: 50 | J10: gr | K10: 26.9 | L10: =I10*K10 -> 1345 | P10: gr | R10: =O10*Q10 -> 0
B11: PAPAS FRANCESAS | C11: 70 | D11: gr | E11: 8.2 | F11: =C11*E11 -> 574 | H11: CADERITA | I11: 50 | J11: gr | K11: 38.7 | L11: =I11*K11 -> 1935 | R11: =O11*Q11 -> 0
F12: =C12*E12 -> 0 | H12: PAPAS FRANCESAS | I12: 70 | J12: gr | K12: 8.2 | L12: =I12*K12 -> 574 | R12: =O12*Q12 -> 0
B13: MATERIAL DE EMPAQUE | H13: MATERIAL DE EMPAQUE | N13: MATERIAL DE EMPAQUE
F14: =C14*140 -> 0 | L14: =I14*140 -> 0 | R14: =O14*140 -> 0
F15: =C15*140 -> 0 | L15: =I15*140 -> 0 | R15: =O15*140 -> 0
F16: =C16*140 -> 0 | L16: =I16*140 -> 0 | R16: =O16*140 -> 0
B17: COSTO + PRECIO DE VENTA | H17: COSTO + PRECIO DE VENTA | N17: COSTO + PRECIO DE VENTA
B18: COSTO DE INGREDIENTES | F18: =(F4+F5+F6+F7+F8+F9+F10+F11+F12+F16) -> 4150.84 | H18: COSTO DE INGREDIENTES | L18: =(L4+L5+L6+L7+L8+L9+L10+L11+L12+L16) -> 5330.84 | N18: COSTO DE INGREDIENTES | R18: =(R4+R5+R6+R7+R8+R9+R10+R11+R12+R16) -> 0
B19: MARGEN DE ERROR O VARIACION 10% | F19: =F18*0.1 -> 415.084 | H19: MARGEN DE ERROR O VARIACION 10% | L19: =L18*0.1 -> 533.084 | N19: MARGEN DE ERROR O VARIACION 10% | R19: =R18*0.1 -> 0
B20: COSTO TOTAL DE LA PREPARACION | F20: =SUM(F18:F19) -> 4565.924 | H20: COSTO TOTAL DE LA PREPARACION | L20: =SUM(L18:L19) -> 5863.924 | N20: COSTO TOTAL DE LA PREPARACION | R20: =SUM(R18:R19) -> 0
B21: PRECIO DE VENTA | F21: 16900 | H21: PRECIO DE VENTA | L21: 17900 | N21: PRECIO DE VENTA | R21: 30000
B24: PASTA CARBONARA
B25: INGREDIENTES | C25: CANTIDAD | D25: UND MEDIDA | E25: COS/GR | F25: VALOR
D26: gr | F26: =C26*E26 -> 0
D27: gr | F27: =C27*E27 -> 0
D28: gr | F28: =C28*E28 -> 0
D29: gr | F29: =C29*E29 -> 0
D30: gr | F30: =C30*E30 -> 0
D31: gr | F31: =C31*E31 -> 0
D32: gr | F32: =C32*E32 -> 0
F33: =C33*E33 -> 0
F34: =C34*E34 -> 0
B35: MATERIAL DE EMPAQUE
F36: =C36*140 -> 0
F37: =C37*140 -> 0
F38: =C38*140 -> 0
B39: COSTO + PRECIO DE VENTA
B40: COSTO DE INGREDIENTES | F40: =(F26+F27+F28+F29+F30+F31+F32+F33+F34+F38) -> 0
B41: MARGEN DE ERROR O VARIACION 10% | F41: =F40*0.1 -> 0
B42: COSTO TOTAL DE LA PREPARACION | F42: =SUM(F40:F41) -> 0
B43: PRECIO DE VENTA | F43: 30000

Sheet ALMUERZOS Y CREMAS 
B2: MILANESA DE CERDO | H2: CUBITOS DE POLLO SALSA DE CILANTRO | N2: CADERITA EN SALSA DE CHAMPIÑON | T2: FILETE DE TILAPIA | Z2: BONDIOLA DE CERDO
B3: INGREDIENTES | C3: CANTIDAD | D3: UND MEDIDA | E3: COS/GR | F3: VALOR | H3: INGREDIENTES | I3: CANTIDAD | J3: UND MEDIDA | K3: COS/GR | L3: VALOR | N3: INGREDIENTES | O3: CANTIDAD | P3: UND MEDIDA | Q3: COS/GR | R3: VALOR | T3: INGREDIENTES | U3: CANTIDAD | V3: UND MEDIDA | W3: COS/GR | X3: VALOR | Z3: INGREDIENTES | AA3: CANTIDAD | AB3: UND MEDIDA | AC3: COS/GR | AD3: VALOR
B4: brazo de cerdo | C4: 150 | D4: gr | E4: 18.9 | F4: =C4*E4 -> 2835 | H4: pechuga de pollo | I4: 150 | J4: gr | K4: 21 | L4: =I4*K4 -> 3150 | N4: caderita | O4: 150 | P4: gr | Q4: 30.33 | R4: =O4*Q4 -> 4549.5 | T4: filete de tilapia | U4: 150 | V4: gr | W4: 32.8 | X4: =U4*W4 -> 4920 | Z4: Bondiola de cerdo | AA4: 150 | AB4: gr | AC4: 20 | AD4: =AA4*AC4 -> 3000
B5: sal | C5: 2 | D5: gr | E5: 2.6 | F5: =C5*E5 -> 5.2 | H5: sal | I5: 4 | J5: gr | K5: 2.6 | L5: =I5*K5 -> 10.4 | N5: sal | O5: 2 | P5: gr | Q5: 2.6 | R5: =O5*Q5 -> 5.2 | T5: sal | U5: 4 | V5: gr | W5: 2.6 | X5: =U5*W5 -> 10.4 | Z5: sal | AA5: 2 | AB5: gr | AC5: 2.6 | AD5: =AA5*AC5 -> 5.2
B6: pimienta | C6: 1 | D6: gr | E6: 58.17 | F6: =C6*E6 -> 58.17 | H6: ajo | I6: 4 | J6: gr | K6: 11 | L6: =I6*K6 -> 44 | N6: pimienta | O6: 1 | P6: gr | Q6: 58.17 | R6: =O6*Q6 -> 58.17 | T6: pimienta | U6: 2 | V6: gr | W6: 58.17 | X6: =U6*W6 -> 116.34 | Z6: pimienta | AA6: 1 | AB6: gr | AC6: 58.17 | AD6: =AA6*AC6 -> 58.17
B7: ajo | C7: 2 | D7: gr | E7: 11 | F7: =C7*E7 -> 22 | H7: pimienta | I7: 2 | J7: gr | K7: 58.17 | L7: =I7*K7 -> 116.34 | N7: pasta de ajo | O7: 3 | P7: gr | Q7: 11 | R7: =O7*Q7 -> 33 | T7: ajo | U7: 6 | V7: gr | W7: 11 | X7: =U7*W7 -> 66 | Z7: ajo | AA7: 2 | AB7: gr | AC7: 11 | AD7: =AA7*AC7 -> 22
B8: panko | C8: 70 | D8: gr | E8: 23.9 | F8: =C8*E8 -> 1673 | H8: cilantro | I8: 4 | J8: gr | K8: 10 | L8: =I8*K8 -> 40 | N8: cebolla cabezona | O8: 20 | P8: gr | Q8: 3.9 | R8: =O8*Q8 -> 78 | T8: limon | U8: 10 | V8: ml | W8: 4.9 | X8: =U8*W8 -> 49 | Z8: Papa cocida | AA8: 100 | AB8: UNID. | AC8: 2.5 | AD8: =AA8*AC8 -> 250
B9: agua | C9: 50 | D9: ml | E9: 26.35 | F9: =C9*E9 -> 1317.5 | H9: crema de leche | I9: 40 | J9: ml | K9: 23.74 | L9: =I9*K9 -> 949.6 | N9: crema de leche | O9: 40 | P9: gr | Q9: 23.74 | R9: =O9*Q9 -> 949.6 | T9: cilantro | U9: 4 | V9: gr | W9: 10 | X9: =U9*W9 -> 40 | Z9: Maduro Cocido | AA9: 125 | AB9: ml | AC9: 2.94 | AD9: =AA9*AC9 -> 367.5
B10: harina | C10: 60 | D10: gr | E10: 2.91 | F10: =C10*E10 -> 174.6 | H10: crema | I10: 1 | J10: gr | K10: 3950 | L10: =I10*K10 -> 3950 | N10: champiñon | O10: 10 | P10: gr | Q10: 31.1 | R10: =O10*Q10 -> 311 | T10: mantequilla | U10: 10 | V10: gr | W10: 16 | X10: =U10*W10 -> 160 | Z10: crema | AA10: 1 | AB10: gr | AC10: 3950 | AD10: =AA10*AC10 -> 3950
B11: crema | C11: 1 | D11: und | E11: 3950 | F11: =C11*E11 -> 3950 | H11: Ensalada | I11: 1 | J11: und | K11: 2278 | L11: =I11*K11 -> 2278 | N11: crema | O11: 1 | P11: gr | Q11: 3950 | R11: =O11*Q11 -> 3950 | T11: crema | U11: 1 | V11: gr | W11: 3950 | X11: =U11*W11 -> 3950 | Z11: Ensalada | AA11: 1 | AB11: und | AC11: 2278 | AD11: =AA11*AC11 -> 2278
B12: Arroz | C12: 100 | D12: gr | E12: 4.11 | F12: =C12*E12 -> 411 | H12: Arroz | I12: 100 | J12: gr | K12: 4.11 | L12: =I12*K12 -> 411 | N12: Arroz | O12: 100 | P12: gr | Q12: 4.11 | R12: =O12*Q12 -> 411 | T12: Arroz | U12: 100 | V12: gr | W12: 4.11 | X12: =U12*W12 -> 411 | Z12: Arroz | AA12: 100 | AB12: gr | AC12: 4.11 | AD12: =AA12*AC12 -> 411
B13: Maduro | C13: 25 | D13: gr | E13: 3.3 | F13: =C13*E13 -> 82.5 | H13: Maduro | I13: 25 | J13: gr | K13: 3.3 | L13: =I13*K13 -> 82.5 | N13: Maduro | O13: 25 | P13: gr | Q13: 3.3 | R13: =O13*Q13 -> 82.5 | T13: Maduro | U13: 25 | V13: gr | W13: 3.3 | X13: =U13*W13 -> 82.5 | Z13: Maduro | AA13: 25 | AB13: gr | AC13: 3.3 | AD13: =AA13*AC13 -> 82.5
B14: Papa | C14: 25 | D14: gr | E14: 4.5 | F14: =C14*E14 -> 112.5 | H14: Papa | I14: 25 | J14: gr | K14: 4.5 | L14: =I14*K14 -> 112.5 | N14: Papa | O14: 25 | P14: gr | Q14: 4.5 | R14: =O14*Q14 -> 112.5 | T14: Papa | U14: 25 | V14: gr | W14: 4.5 | X14: =U14*W14 -> 112.5 | Z14: Papa | AA14: 25 | AB14: gr | AC14: 4.5 | AD14: =AA14*AC14 -> 112.5
B15: Ensalada | C15: 1 | D15: und | E15: 2278 | F15: =C15*E15 -> 2278 | H15: Total | L15: =SUM(L4:L14) -> 11144.34 | N15: Ensalada | O15: 1 | P15: und | Q15: 2278 | R15: =O15*Q15 -> 2278 | T15: Ensalada | U15: 1 | V15: und | W15: 2278 | X15: =U15*W15 -> 2278 | Z15: Total | AD15: =SUM(AD4:AD14) -> 10536.87
B16: Total | F16: =SUM(F4:F15) -> 12919.47 | H16: MATERIAL DE EMPAQUE | N16: Total | R16: =SUM(R4:R15) -> 12818.47 | T16: Total | X16: =SUM(X4:X15) -> 12195.74 | Z16: MATERIAL DE EMPAQUE
B17: MATERIAL DE EMPAQUE | H17: Enpaque Roauter | I17: 1 | J17: und | K17: 1600 | L17: =I17*K17 -> 1600 | N17: MATERIAL DE EMPAQUE | T17: MATERIAL DE EMPAQUE | Z17: Enpaque Roauter | AA17: 1 | AB17: und | AC17: 1600 | AD17: =AA17*AC17 -> 1600
B18: Enpaque Roauter | C18: 1 | D18: und | E18: 1600 | F18: =C18*E18 -> 1600 | H18: tenedor y cuchillo | I18: 2 | J18: und | K18: 70 | L18: =I18*K18 -> 140 | N18: Enpaque Roauter | O18: 1 | P18: und | Q18: 1600 | R18: =O18*Q18 -> 1600 | T18: Enpaque Roauter | U18: 1 | V18: und | W18: 1600 | X18: =U18*W18 -> 1600 | Z18: tenedor y cuchillo | AA18: 2 | AB18: und | AC18: 70 | AD18: =AA18*AC18 -> 140
B19: tenedor y cuchillo | C19: 2 | D19: und | E19: 70 | F19: =C19*E19 -> 140 | H19: Total | L19: =SUM(L17:L18) -> 1740 | N19: tenedor y cuchillo | O19: 2 | P19: und | Q19: 70 | R19: =O19*Q19 -> 140 | T19: tenedor y cuchillo | U19: 2 | V19: und | W19: 70 | X19: =U19*W19 -> 140 | AD19: =SUM(AD17:AD18) -> 1740
B20: Total | F20: =SUM(F18:F19) -> 1740 | H20: COSTO + PRECIO DE VENTA | N20: Total | R20: =SUM(R18:R19) -> 1740 | T20: Total | X20: =SUM(X18:X19) -> 1740 | Z20: COSTO + PRECIO DE VENTA
B21: COSTO + PRECIO DE VENTA | H21: COSTO DE INGREDIENTES | L21: =L19+L15 -> 12884.34 | N21: COSTO + PRECIO DE VENTA | T21: COSTO + PRECIO DE VENTA | Z21: COSTO DE INGREDIENTES | AD21: =AD19+AD15 -> 12276.87
B22: COSTO DE INGREDIENTES | F22: =F20+F16 -> 14659.47 | H22: MARGEN DE ERROR O VARIACION 10% | L22: =L21*0.1 -> 1288.434 | N22: COSTO DE INGREDIENTES | R22: =R20+R16 -> 14558.47 | T22: COSTO DE INGREDIENTES | X22: =X20+X16 -> 13935.74 | Z22: MARGEN DE ERROR O VARIACION 10% | AD22: =AD21*0.1 -> 1227.687
B23: MARGEN DE ERROR O VARIACION 10% | F23: =F22*0.1 -> 1465.947 | H23: COSTO TOTAL DE LA PREPARACION | L23: =SUM(L21:L22) -> 14172.774 | N23: MARGEN DE ERROR O VARIACION 10% | R23: =R22*0.1 -> 1455.847 | T23: MARGEN DE ERROR O VARIACION 10% | X23: =X22*0.1 -> 1393.574 | Z23: COSTO TOTAL DE LA PREPARACION | AD23: =SUM(AD21:AD22) -> 13504.557
B24: COSTO TOTAL DE LA PREPARACION | F24: =SUM(F22:F23) -> 16125.417 | H24: PRECIO DE VENTA | L24: 24900 | N24: COSTO TOTAL DE LA PREPARACION | R24: =SUM(R22:R23) -> 16014.317 | T24: COSTO TOTAL DE LA PREPARACION | X24: =SUM(X22:X23) -> 15329.314 | Z24: PRECIO DE VENTA | AD24: 25900
B25: PRECIO DE VENTA | F25: 27900 | N25: PRECIO DE VENTA | R25: 27900 | T25: PRECIO DE VENTA | X25: 27900

Sheet PLATOS
B2: CHICHARON OREADO | H2: POLLO DORADO | N2: ENSALADA DE BONDIOLA
B3: INGREDIENTES | C3: CANTIDAD | D3: UND MEDIDA | E3: COS/GR | F3: VALOR | H3: INGREDIENTES | I3: CANTIDAD | J3: UND MEDIDA | K3: COS/GR | L3: VALOR | N3: INGREDIENTES | O3: CANTIDAD | P3: UND MEDIDA | Q3: COS/GR | R3: VALOR
B4: Chicharrón Oreado | C4: 250 | D4: gr | E4: 26.9 | F4: =C4*E4 -> 6725 | H4: Churrasquillo de pollo | I4: 470 | J4: gr | K4: 11.5 | L4: =I4*K4 -> 5405 | N4: Jamón de Bondiola Acaramelada | O4: 100 | P4: gr | Q4: 24.4 | R4: =O4*Q4 -> 2440
B5: Mix de papas | C5: 140 | D5: gr | E5: 5.5 | F5: =C5*E5 -> 770 | H5: Pure de maduro | I5: 200 | J5: gr | K5: 10 | L5: =I5*K5 -> 2000 | N5: Mix de Lechugas | O5: 100 | P5: gr | Q5: 20 | R5: =O5*Q5 -> 2000
B6: Miel de Caña | C6: 80 | D6: gr | E6: 8.14 | F6: =C6*E6 -> 651.2 | H6: Salsa artesanal de tomate y romero | I6: 100 | J6: gr | K6: 6.25 | L6: =I6*K6 -> 625 | N6: Cebolla Encurtida | O6: 40 | P6: gr | Q6: 12.6 | R6: =O6*Q6 -> 504
B7: ensalada | C7: 100 | D7: gr | E7: 20.71 | F7: =C7*E7 -> 2071 | H7: Jardinera | I7: 100 | J7: gr | K7: 10 | L7: =I7*K7 -> 1000 | N7: Miel de Caña | O7: 10 | P7: gr | Q7: 8.14 | R7: =O7*Q7 -> 81.4
B8: alioli cilantro | C8: 40 | D8: gr | E8: 10.8 | F8: =C8*E8 -> 432 | L8: =I8*K8 -> 0 | N8: chuney de piña | O8: 10 | P8: gr | Q8: 8.8 | R8: =O8*Q8 -> 88
B9: Chuney de piña | C9: 15 | D9: gr | E9: 8.8 | F9: =C9*E9 -> 132 | L9: =I9*K9 -> 0 | N9: queso costeño | O9: 20 | P9: gr | Q9: 22 | R9: =O9*Q9 -> 440
F10: =C10*E10 -> 0 | L10: =I10*K10 -> 0 | N10: almendras rebanadas | O10: 10 | P10: gr | Q10: 120 | R10: =O10*Q10 -> 1200
F11: =C11*E11 -> 0 | L11: =I11*K11 -> 0 | N11: tomate cherry | O11: 30 | P11: gr | Q11: 18.36 | R11: =O11*Q11 -> 550.8
F12: =SUM(F4:F11) -> 10781.2 | L12: =SUM(L4:L11) -> 9030 | N12: uchuva | O12: 30 | P12: gr | Q12: 14.76 | R12: =O12*Q12 -> 442.8
B13: MATERIAL DE EMPAQUE | H13: MATERIAL DE EMPAQUE | R13: =SUM(R4:R12) -> 7747
B14: Enpaque Roauter | C14: 1 | D14: und | E14: 1600 | F14: =C14*E14 -> 1600 | H14: Enpaque Roauter | I14: 1 | J14: und | K14: 1600 | L14: =I14*K14 -> 1600 | N14: MATERIAL DE EMPAQUE
B15: tenedor y cuchillo | C15: 2 | D15: und | E15: 70 | F15: =C15*E15 -> 140 | H15: tenedor y cuchillo | I15: 2 | J15: und | K15: 70 | L15: =I15*K15 -> 140 | N15: Enpaque Roauter | O15: 1 | P15: und | Q15: 1600 | R15: =O15*Q15 -> 1600
B16: Total | F16: =SUM(F14:F15) -> 1740 | H16: Total | L16: =SUM(L14:L15) -> 1740 | N16: tenedor y cuchillo | O16: 2 | P16: und | Q16: 70 | R16: =O16*Q16 -> 140
B17: COSTO + PRECIO DE VENTA | H17: COSTO + PRECIO DE VENTA | N17: Total | R17: =SUM(R15:R16) -> 1740
B18: COSTO DE INGREDIENTES | F18: =F12+F16 -> 12521.2 | H18: COSTO DE INGREDIENTES | L18: =L12+L16 -> 10770 | N18: COSTO + PRECIO DE VENTA
B19: MARGEN DE ERROR O VARIACION 10% | F19: =F18*0.1 -> 1252.12 | H19: MARGEN DE ERROR O VARIACION 10% | L19: =L18*0.1 -> 1077 | N19: COSTO DE INGREDIENTES | R19: =R13+R17 -> 9487
B20: COSTO TOTAL DE LA PREPARACION | F20: =SUM(F18:F19) -> 13773.32 | H20: COSTO TOTAL DE LA PREPARACION | L20: =SUM(L18:L19) -> 11847 | N20: MARGEN DE ERROR O VARIACION 10% | R20: =R19*0.1 -> 948.7
B21: PRECIO DE VENTA | F21: 47000 | H21: PRECIO DE VENTA | L21: 47000 | N21: COSTO TOTAL DE LA PREPARACION | R21: =SUM(R19:R20) -> 10435.7
N22: PRECIO DE VENTA | R22: 40000
B24: COSTILLA SOUS VIDE | H24: HAMBURGUESA MALAGANA
B25: INGREDIENTES | C25: CANTIDAD | D25: UND MEDIDA | E25: COS/GR | F25: VALOR | H25: INGREDIENTES | I25: CANTIDAD | J25: UND MEDIDA | K25: COS/GR | L25: VALOR | N25: HAMBURGUESA CACIQUE
B26: COSTILLA TIPO LLANERA | C26: 500 | D26: gr | E26: 21 | F26: =C26*E26 -> 10500 | H26: Pan brioche | I26: 1 | J26: Und | K26: 1050 | L26: =I26*K26 -> 1050 | N26: INGREDIENTES | O26: CANTIDAD | P26: UND MEDIDA | Q26: COS/GR | R26: VALOR
B27: REDUCCION DE FLOR DE JAMAICA | C27: 90 | D27: gr | F27: =C27*E27 -> 0 | H27: mantequilla de chontaduro | I27: 10 | J27: gr | K27: 18.5 | L27: =I27*K27 -> 185 | N27: Carne angus americana | O27: 180 | P27: gr | Q27: 22.9 | R27: =O27*Q27 -> 4122
B28: ENSALADA FRESCA | C28: 100 | D28: gr | E28: 21 | F28: =C28*E28 -> 2100 | H28: carne artesanal | I28: 150 | J28: gr | K28: 22.9 | L28: =I28*K28 -> 3435 | N28: queso philadelphia | O28: 40 | P28: gr | Q28: 32.28 | R28: =O28*Q28 -> 1291.2
B29: PAPAS AMARILLAS EN CASCO | C29: 140 | D29: gr | E29: 5.5 | F29: =C29*E29 -> 770 | H29: Dip de tocineta | I29: 30 | J29: gr | K29: 24.47 | L29: =I29*K29 -> 734.1 | N29: cebolla crispy | O29: 30 | P29: gr | Q29: 4.4 | R29: =O29*Q29 -> 132
B30: ALIOLI DE CILANTRO | C30: 40 | D30: gr | E30: 10.8 | F30: =C30*E30 -> 432 | H30: cebolla caramelizada en uchuva | I30: 30 | J30: gr | K30: 5.2 | L30: =I30*K30 -> 156 | N30: lechuga de temporada | O30: 10 | P30: gr | Q30: 20 | R30: =O30*Q30 -> 200
F31: =C31*E31 -> 0 | H31: lechuga de temporada | I31: 10 | J31: gr | K31: 20 | L31: =I31*K31 -> 200 | N31: tomate milano | O31: 30 | P31: gr | Q31: 7.98 | R31: =O31*Q31 -> 239.4
F32: =C32*E32 -> 0 | H32: tomate milano | I32: 30 | J32: gr | K32: 7.98 | L32: =I32*K32 -> 239.4 | N32: pan brioche artesanal | O32: 1 | P32: gr | Q32: 1050 | R32: =O32*Q32 -> 1050
F33: =C33*E33 -> 0 | H33: mix de papa | I33: 140 | J33: gr | K33: 5.5 | L33: =I33*K33 -> 770 | N33: tocineta | O33: 25 | P33: gr | Q33: 25.9 | R33: =O33*Q33 -> 647.5
H34: alioli cilantro | I34: 40 | J34: gr | K34: 10.8 | L34: =I34*K34 -> 432 | N34: Dip de pepinillos | O34: 40 | P34: gr | R34: =O34*Q34 -> 0
F35: =SUM(F26:F34) -> 13802 | L35: =SUM(L26:L34) -> 7201.5 | N35: mix de papas | O35: 140 | P35: gr | Q35: 5.5 | R35: =O35*Q35 -> 770
B36: MATERIAL DE EMPAQUE | H36: MATERIAL DE EMPAQUE | N36: salsa de la casa | O36: 40 | P36: gr | Q36: 10.8 | R36: =O36*Q36 -> 432
B37: Enpaque Roauter | C37: 1 | D37: und | E37: 1600 | F37: =C37*E37 -> 1600 | H37: Enpaque Roauter | I37: 1 | J37: und | K37: 1600 | L37: =I37*K37 -> 1600 | N37: MATERIAL DE EMPAQUE
B38: tenedor y cuchillo | C38: 2 | D38: und | E38: 70 | F38: =C38*E38 -> 140 | H38: tenedor y cuchillo | I38: 2 | J38: und | K38: 70 | L38: =I38*K38 -> 140 | R38: =O38*140 -> 0
B39: Total | F39: =SUM(F37:F38) -> 1740 | H39: Total | L39: =SUM(L37:L38) -> 1740 | R39: =O39*140 -> 0
B40: COSTO + PRECIO DE VENTA | H40: COSTO + PRECIO DE VENTA | R40: =O40*140 -> 0
B41: COSTO DE INGREDIENTES | F41: =F35+F39 -> 15542 | H41: COSTO DE INGREDIENTES | L41: =L35+L39 -> 8941.5 | N41: COSTO + PRECIO DE VENTA
B42: MARGEN DE ERROR O VARIACION 10% | F42: =F41*0.1 -> 1554.2 | H42: MARGEN DE ERROR O VARIACION 10% | L42: =L41*0.1 -> 894.15 | N42: COSTO DE INGREDIENTES | R42: =(R27+R28+R29+R30+R31+R32+R33+R34+R35+R36+R40) -> 8884.1
...

Sheet PIZZAS
B2: MASA PARA PIZZA X 4 | H2: CARNES | N2: MARGARITA | T2: SAMBA | Z2: ORIGEN
B3: INGREDIENTES | C3: CANTIDAD | D3: UND MEDIDA | E3: COS/GR | F3: VALOR | H3: INGREDIENTES | I3: CANTIDAD | J3: UND MEDIDA | K3: COS/GR | L3: VALOR | N3: INGREDIENTES | O3: CANTIDAD | P3: UND MEDIDA | Q3: COS/GR | R3: VALOR | T3: INGREDIENTES | U3: CANTIDAD | V3: UND MEDIDA | W3: COS/GR | X3: VALOR | Z3: INGREDIENTES | AA3: CANTIDAD | AB3: UND MEDIDA | AC3: COS/GR | AD3: VALOR
B4: Harina de trigo | C4: 600 | D4: gr | E4: 9.2 | F4: =C4*E4 -> 5520 | H4: Masa para Pizza | I4: 150 | J4: gr | K4: 10.4 | L4: =I4*K4 -> 1560 | N4: Masa para Pizza | O4: 150 | P4: gr | Q4: 10.4 | R4: =O4*Q4 -> 1560 | T4: napolitana | U4: 60 | V4: gr | W4: 34.7 | X4: =U4*W4 -> 2082 | Z4: napolitana | AA4: 60 | AB4: gr | AC4: 34.7 | AD4: =AA4*AC4 -> 2082
B5: Levadura | C5: 5 | D5: gr | E5: 23.8 | F5: =C5*E5 -> 119 | H5: Salsa Napolitana | I5: 80 | J5: gr | K5: 11 | L5: =I5*K5 -> 880 | N5: Salsa Napolitana | O5: 80 | P5: gr | Q5: 34.7 | R5: =O5*Q5 -> 2776 | T5: queso mozarella | U5: 150 | V5: gr | W5: 23.2 | X5: =U5*W5 -> 3480 | Z5: queso mozarella | AA5: 150 | AB5: gr | AC5: 23.2 | AD5: =AA5*AC5 -> 3480
B6: Sal | C6: 3 | D6: gr | E6: 2.6 | F6: =C6*E6 -> 7.8 | H6: Queso Mozarrella | I6: 150 | J6: gr | K6: 19.5 | L6: =I6*K6 -> 2925 | N6: Tomate Chery | O6: 20 | P6: gr | Q6: 34 | R6: =O6*Q6 -> 680 | T6: maduro | U6: 40 | V6: gr | W6: 5.16 | X6: =U6*W6 -> 206.4 | Z6: chorizo | AA6: 47 | AB6: gr | AC6: 52.63 | AD6: =AA6*AC6 -> 2473.61
B7: Agua | C7: 250 | D7: ml | E7: 26 | F7: =C7*E7 -> 6500 | H7: Bondiola | I7: 40 | J7: gr | K7: 36 | L7: =I7*K7 -> 1440 | N7: Queso Mozarrella | O7: 150 | P7: gr | Q7: 19.5 | R7: =O7*Q7 -> 2925 | T7: tocineta | U7: 80 | V7: gr | W7: 34.8 | X7: =U7*W7 -> 2784 | Z7: merma de carne | AA7: 90 | AB7: gr | AC7: 58 | AD7: =AA7*AC7 -> 5220
F8: =C8*E8 -> 0 | H8: Tocineta | I8: 20 | J8: gr | K8: 23 | L8: =I8*K8 -> 460 | N8: Albahaca Genovesa | O8: 5 | P8: gr | Q8: 11 | R8: =O8*Q8 -> 55 | T8: masa de pizza | U8: 150 | V8: gr | W8: 10.4 | X8: =U8*W8 -> 1560 | Z8: chimichurri | AA8: 20 | AB8: gr | AC8: 24.03 | AD8: =AA8*AC8 -> 480.6
F9: =C9*E9 -> 0 | H9: Miel Caña | I9: 5 | J9: ml | K9: 0 | L9: =I9*K9 -> 0 | N9: Aceite de Oliva | O9: 5 | P9: ml | Q9: 8 | R9: =O9*Q9 -> 40 | X9: =U9*W9 -> 0 | Z9: masa de pizza | AA9: 150 | AB9: gr | AC9: 10.4 | AD9: =AA9*AC9 -> 1560
B10: MATERIAL DE EMPAQUE | H10: MATERIAL DE EMPAQUE | N10: MATERIAL DE EMPAQUE | T10: MATERIAL DE EMPAQUE | Z10: MATERIAL DE EMPAQUE
F11: =C11*140 -> 0 | H11: Caja de Pizza | I11: 1 | J11: und | K11: 1800 | L11: =I11*K11 -> 1800 | N11: Caja de Pizza | O11: 1 | P11: und | Q11: 1800 | R11: =O11*Q11 -> 1800 | T11: Caja de Pizza | U11: 1 | V11: und | W11: 1800 | X11: =U11*W11 -> 1800 | Z11: Caja de Pizza | AA11: 1 | AB11: und | AC11: 1800 | AD11: =AA11*AC11 -> 1800
F12: =C12*140 -> 0 | L12: =I12*140 -> 0 | R12: =O12*140 -> 0 | X12: =U12*140 -> 0 | AD12: =AA12*140 -> 0
F13: =C13*140 -> 0 | L13: =SUM(L11:L12) -> 1800 | R13: =SUM(R11:R12) -> 1800 | X13: =SUM(X11:X12) -> 1800 | AD13: =SUM(AD11:AD12) -> 1800
B14: COSTO + PRECIO DE VENTA | H14: COSTO + PRECIO DE VENTA | N14: COSTO + PRECIO DE VENTA | T14: COSTO + PRECIO DE VENTA | Z14: COSTO + PRECIO DE VENTA
B15: COSTO DE INGREDIENTES | F15: =(F4+F5+F6+F7+F8+F9+F11+F12+F13) -> 12146.8 | H15: COSTO DE INGREDIENTES | L15: =(L4+L5+L6+L7+L8+L9+L13) -> 9065 | N15: COSTO DE INGREDIENTES | R15: =(R4+R5+R6+R7+R8+R9+R11+R12+R13) -> 11636 | T15: COSTO DE INGREDIENTES | X15: =(X4+X5+X6+X7+X8+X9+X11+X12+X13) -> 13712.4 | Z15: COSTO DE INGREDIENTES | AD15: =(AD4+AD5+AD6+AD7+AD8+AD9+AD11+AD12+AD13) -> 18896.21
B16: MARGEN DE ERROR O VARIACION 10% | F16: =F15*0.1 -> 1214.68 | H16: MARGEN DE ERROR O VARIACION 10% | L16: =L15*0.1 -> 906.5 | N16: MARGEN DE ERROR O VARIACION 10% | R16: =R15*0.1 -> 1163.6 | T16: MARGEN DE ERROR O VARIACION 10% | X16: =X15*0.1 -> 1371.24 | Z16: MARGEN DE ERROR O VARIACION 10% | AD16: =AD15*0.1 -> 1889.621
B17: COSTO TOTAL DE LA PREPARACION | F17: =SUM(F15:F16) -> 13361.48 | H17: COSTO TOTAL DE LA PREPARACION | L17: =SUM(L15:L16) -> 9971.5 | N17: COSTO TOTAL DE LA PREPARACION | R17: =SUM(R15:R16) -> 12799.6 | T17: COSTO TOTAL DE LA PREPARACION | X17: =SUM(X15:X16) -> 15083.64 | Z17: COSTO TOTAL DE LA PREPARACION | AD17: =SUM(AD15:AD16) -> 20785.831
B18: PRECIO DE VENTA | F18: =F17 -> 13361.48 | H18: PRECIO DE VENTA | L18: 38000 | N18: PRECIO DE VENTA | R18: 30000 | T18: PRECIO DE VENTA | X18: 32000 | Z18: PRECIO DE VENTA | AD18: 38000
